Workbook

Sheet Özet
A1: TÜBİTAK Mevzuat RAG — İhtiyaç Karşılama Matrisi
A2: Sürüm 2.3 · Sahip: Batur Alp · Oluşturma: 2026-10-27
A3: Kaynak: docs/requirements/ihtiyaclar.yaml (tek kaynak). Bu dosya build.py ile üretilir; durum güncellemeleri YAML'da yapılıp dosya yeniden üretilmelidir.
A5: Genel durum
A6: Gösterge | B6: Değer
A7: Toplam ihtiyaç | B7: =COUNTA(İhtiyaçlar!$A$2:$A$98) -> 97
A8: Bekliyor | B8: =COUNTIF(İhtiyaçlar!$H$2:$H$98,"Bekliyor") -> 0
A9: Karşılandı | B9: =COUNTIF(İhtiyaçlar!$H$2:$H$98,"Karşılandı") -> 89
A10: Kısmi | B10: =COUNTIF(İhtiyaçlar!$H$2:$H$98,"Kısmi") -> 6
A11: Karşılanmadı | B11: =COUNTIF(İhtiyaçlar!$H$2:$H$98,"Karşılanmadı") -> 2
A12: Kapsam dışı | B12: =COUNTIF(İhtiyaçlar!$H$2:$H$98,"Kapsam dışı") -> 0
A13: Karşılanma oranı (kapsam içi) | B13: =IFERROR(B9/(B7-B12),0) -> 0.91752577
A14: Zorunlu ihtiyaçlarda karşılanma | B14: =IFERROR(COUNTIFS(İhtiyaçlar!$F$2:$F$98,"Zorunlu",İhtiyaçlar!$H$2:$H$98,"Karşılandı")/COUNTIF(İhtiyaçlar!$F$2:$F$98,"Zorunlu"),0) -> 0.95833333
A16: Kategoriye göre
A17: Kategori | B17: Toplam | C17: Karşılandı | D17: Kısmi | E17: Karşılanmadı | F17: Kapsam dışı | G17: Bekliyor
A18: Ayrıştırma ve temizleme | B18: =COUNTIF(İhtiyaçlar!$B$2:$B$98,A18) -> 7 | C18: =COUNTIFS(İhtiyaçlar!$B$2:$B$98,$A18,İhtiyaçlar!$H$2:$H$98,"Karşılandı") -> 6 | D18: =COUNTIFS(İhtiyaçlar!$B$2:$B$98,$A18,İhtiyaçlar!$H$2:$H$98,"Kısmi") -> 1 | E18: =COUNTIFS(İhtiyaçlar!$B$2:$B$98,$A18,İhtiyaçlar!$H$2:$H$98,"Karşılanmadı") -> 0 | F18: =COUNTIFS(İhtiyaçlar!$B$2:$B$98,$A18,İhtiyaçlar!$H$2:$H$98,"Kapsam dışı") -> 0 | G18: =COUNTIFS(İhtiyaçlar!$B$2:$B$98,$A18,İhtiyaçlar!$H$2:$H$98,"Bekliyor") -> 0
A19: Parçalama (chunking) | B19: =COUNTIF(İhtiyaçlar!$B$2:$B$98,A19) -> 3 | C19: =COUNTIFS(İhtiyaçlar!$B$2:$B$98,$A19,İhtiyaçlar!$H$2:$H$98,"Karşılandı") -> 3 | D19: =COUNTIFS(İhtiyaçlar!$B$2:$B$98,$A19,İhtiyaçlar!$H$2:$H$98,"Kısmi") -> 0 | E19: =COUNTIFS(İhtiyaçlar!$B$2:$B$98,$A19,İhtiyaçlar!$H$2:$H$98,"Karşılanmadı") -> 0 | F19: =COUNTIFS(İhtiyaçlar!$B$2:$B$98,$A19,İhtiyaçlar!$H$2:$H$98,"Kapsam dışı") -> 0 | G19: =COUNTIFS(İhtiyaçlar!$B$2:$B$98,$A19,İhtiyaçlar!$H$2:$H$98,"Bekliyor") -> 0
A20: İndeksleme | B20: =COUNTIF(İhtiyaçlar!$B$2:$B$98,A20) -> 2 | C20: =COUNTIFS(İhtiyaçlar!$B$2:$B$98,$A20,İhtiyaçlar!$H$2:$H$98,"Karşılandı") -> 2 | D20: =COUNTIFS(İhtiyaçlar!$B$2:$B$98,$A20,İhtiyaçlar!$H$2:$H$98,"Kısmi") -> 0 | E20: =COUNTIFS(İhtiyaçlar!$B$2:$B$98,$A20,İhtiyaçlar!$H$2:$H$98,"Karşılanmadı") -> 0 | F20: =COUNTIFS(İhtiyaçlar!$B$2:$B$98,$A20,İhtiyaçlar!$H$2:$H$98,"Kapsam dışı") -> 0 | G20: =COUNTIFS(İhtiyaçlar!$B$2:$B$98,$A20,İhtiyaçlar!$H$2:$H$98,"Bekliyor") -> 0
A21: Arama ve yeniden sıralama | B21: =COUNTIF(İhtiyaçlar!$B$2:$B$98,A21) -> 5 | C21: =COUNTIFS(İhtiyaçlar!$B$2:$B$98,$A21,İhtiyaçlar!$H$2:$H$98,"Karşılandı") -> 5 | D21: =COUNTIFS(İhtiyaçlar!$B$2:$B$98,$A21,İhtiyaçlar!$H$2:$H$98,"Kısmi") -> 0 | E21: =COUNTIFS(İhtiyaçlar!$B$2:$B$98,$A21,İhtiyaçlar!$H$2:$H$98,"Karşılanmadı") -> 0 | F21: =COUNTIFS(İhtiyaçlar!$B$2:$B$98,$A21,İhtiyaçlar!$H$2:$H$98,"Kapsam dışı") -> 0 | G21: =COUNTIFS(İhtiyaçlar!$B$2:$B$98,$A21,İhtiyaçlar!$H$2:$H$98,"Bekliyor") -> 0
A22: Cevap üretimi ve atıf | B22: =COUNTIF(İhtiyaçlar!$B$2:$B$98,A22) -> 5 | C22: =COUNTIFS(İhtiyaçlar!$B$2:$B$98,$A22,İhtiyaçlar!$H$2:$H$98,"Karşılandı") -> 5 | D22: =COUNTIFS(İhtiyaçlar!$B$2:$B$98,$A22,İhtiyaçlar!$H$2:$H$98,"Kısmi") -> 0 | E22: =COUNTIFS(İhtiyaçlar!$B$2:$B$98,$A22,İhtiyaçlar!$H$2:$H$98,"Karşılanmadı") -> 0 | F22: =COUNTIFS(İhtiyaçlar!$B$2:$B$98,$A22,İhtiyaçlar!$H$2:$H$98,"Kapsam dışı") -> 0 | G22: =COUNTIFS(İhtiyaçlar!$B$2:$B$98,$A22,İhtiyaçlar!$H$2:$H$98,"Bekliyor") -> 0
A23: Güvenlik önlemleri (guardrail) | B23: =COUNTIF(İhtiyaçlar!$B$2:$B$98,A23) -> 9 | C23: =COUNTIFS(İhtiyaçlar!$B$2:$B$98,$A23,İhtiyaçlar!$H$2:$H$98,"Karşılandı") -> 6 | D23: =COUNTIFS(İhtiyaçlar!$B$2:$B$98,$A23,İhtiyaçlar!$H$2:$H$98,"Kısmi") -> 2 | E23: =COUNTIFS(İhtiyaçlar!$B$2:$B$98,$A23,İhtiyaçlar!$H$2:$H$98,"Karşılanmadı") -> 1 | F23: =COUNTIFS(İhtiyaçlar!$B$2:$B$98,$A23,İhtiyaçlar!$H$2:$H$98,"Kapsam dışı") -> 0 | G23: =COUNTIFS(İhtiyaçlar!$B$2:$B$98,$A23,İhtiyaçlar!$H$2:$H$98,"Bekliyor") -> 0
A24: Test seti | B24: =COUNTIF(İhtiyaçlar!$B$2:$B$98,A24) -> 12 | C24: =COUNTIFS(İhtiyaçlar!$B$2:$B$98,$A24,İhtiyaçlar!$H$2:$H$98,"Karşılandı") -> 11 | D24: =COUNTIFS(İhtiyaçlar!$B$2:$B$98,$A24,İhtiyaçlar!$H$2:$H$98,"Kısmi") -> 0 | E24: =COUNTIFS(İhtiyaçlar!$B$2:$B$98,$A24,İhtiyaçlar!$H$2:$H$98,"Karşılanmadı") -> 1 | F24: =COUNTIFS(İhtiyaçlar!$B$2:$B$98,$A24,İhtiyaçlar!$H$2:$H$98,"Kapsam dışı") -> 0 | G24: =COUNTIFS(İhtiyaçlar!$B$2:$B$98,$A24,İhtiyaçlar!$H$2:$H$98,"Bekliyor") -> 0
A25: Arama değerlendirmesi | B25: =COUNTIF(İhtiyaçlar!$B$2:$B$98,A25) -> 6 | C25: =COUNTIFS(İhtiyaçlar!$B$2:$B$98,$A25,İhtiyaçlar!$H$2:$H$98,"Karşılandı") -> 5 | D25: =COUNTIFS(İhtiyaçlar!$B$2:$B$98,$A25,İhtiyaçlar!$H$2:$H$98,"Kısmi") -> 1 | E25: =COUNTIFS(İhtiyaçlar!$B$2:$B$98,$A25,İhtiyaçlar!$H$2:$H$98,"Karşılanmadı") -> 0 | F25: =COUNTIFS(İhtiyaçlar!$B$2:$B$98,$A25,İhtiyaçlar!$H$2:$H$98,"Kapsam dışı") -> 0 | G25: =COUNTIFS(İhtiyaçlar!$B$2:$B$98,$A25,İhtiyaçlar!$H$2:$H$98,"Bekliyor") -> 0
A26: Cevap değerlendirmesi | B26: =COUNTIF(İhtiyaçlar!$B$2:$B$98,A26) -> 11 | C26: =COUNTIFS(İhtiyaçlar!$B$2:$B$98,$A26,İhtiyaçlar!$H$2:$H$98,"Karşılandı") -> 10 | D26: =COUNTIFS(İhtiyaçlar!$B$2:$B$98,$A26,İhtiyaçlar!$H$2:$H$98,"Kısmi") -> 1 | E26: =COUNTIFS(İhtiyaçlar!$B$2:$B$98,$A26,İhtiyaçlar!$H$2:$H$98,"Karşılanmadı") -> 0 | F26: =COUNTIFS(İhtiyaçlar!$B$2:$B$98,$A26,İhtiyaçlar!$H$2:$H$98,"Kapsam dışı") -> 0 | G26: =COUNTIFS(İhtiyaçlar!$B$2:$B$98,$A26,İhtiyaçlar!$H$2:$H$98,"Bekliyor") -> 0
A27: Deney karşılaştırma ve dokümantasyon | B27: =COUNTIF(İhtiyaçlar!$B$2:$B$98,A27) -> 4 | C27: =COUNTIFS(İhtiyaçlar!$B$2:$B$98,$A27,İhtiyaçlar!$H$2:$H$98,"Karşılandı") -> 4 | D27: =COUNTIFS(İhtiyaçlar!$B$2:$B$98,$A27,İhtiyaçlar!$H$2:$H$98,"Kısmi") -> 0 | E27: =COUNTIFS(İhtiyaçlar!$B$2:$B$98,$A27,İhtiyaçlar!$H$2:$H$98,"Karşılanmadı") -> 0 | F27: =COUNTIFS(İhtiyaçlar!$B$2:$B$98,$A27,İhtiyaçlar!$H$2:$H$98,"Kapsam dışı") -> 0 | G27: =COUNTIFS(İhtiyaçlar!$B$2:$B$98,$A27,İhtiyaçlar!$H$2:$H$98,"Bekliyor") -> 0
A28: Web arayüzü | B28: =COUNTIF(İhtiyaçlar!$B$2:$B$98,A28) -> 6 | C28: =COUNTIFS(İhtiyaçlar!$B$2:$B$98,$A28,İhtiyaçlar!$H$2:$H$98,"Karşılandı") -> 6 | D28: =COUNTIFS(İhtiyaçlar!$B$2:$B$98,$A28,İhtiyaçlar!$H$2:$H$98,"Kısmi") -> 0 | E28: =COUNTIFS(İhtiyaçlar!$B$2:$B$98,$A28,İhtiyaçlar!$H$2:$H$98,"Karşılanmadı") -> 0 | F28: =COUNTIFS(İhtiyaçlar!$B$2:$B$98,$A28,İhtiyaçlar!$H$2:$H$98,"Kapsam dışı") -> 0 | G28: =COUNTIFS(İhtiyaçlar!$B$2:$B$98,$A28,İhtiyaçlar!$H$2:$H$98,"Bekliyor") -> 0
A29: Barındırılan sürüm (Hugging Face Spaces) | B29: =COUNTIF(İhtiyaçlar!$B$2:$B$98,A29) -> 3 | C29: =COUNTIFS(İhtiyaçlar!$B$2:$B$98,$A29,İhtiyaçlar!$H$2:$H$98,"Karşılandı") -> 3 | D29: =COUNTIFS(İhtiyaçlar!$B$2:$B$98,$A29,İhtiyaçlar!$H$2:$H$98,"Kısmi") -> 0 | E29: =COUNTIFS(İhtiyaçlar!$B$2:$B$98,$A29,İhtiyaçlar!$H$2:$H$98,"Karşılanmadı") -> 0 | F29: =COUNTIFS(İhtiyaçlar!$B$2:$B$98,$A29,İhtiyaçlar!$H$2:$H$98,"Kapsam dışı") -> 0 | G29: =COUNTIFS(İhtiyaçlar!$B$2:$B$98,$A29,İhtiyaçlar!$H$2:$H$98,"Bekliyor") -> 0
... A34: Güvenlik, gizlilik ve dil | B34: =COUNTIF(İhtiyaçlar!$B$2:$B$98,A34) -> 6 | C34: =COUNTIFS(İhtiyaçlar!$B$2:$B$98,$A34,İhtiyaçlar!$H$2:$H$98,"Karşılandı") -> 5 | D34: =COUNTIFS(İhtiyaçlar!$B$2:$B$98,$A34,İhtiyaçlar!$H$2:$H$98,"Kısmi") -> 1 | E34: =COUNTIFS(İhtiyaçlar!$B$2:$B$98,$A34,İhtiyaçlar!$H$2:$H$98,"Karşılanmadı") -> 0 | F34: =COUNTIFS(İhtiyaçlar!$B$2:$B$98,$A34,İhtiyaçlar!$H$2:$H$98,"Kapsam dışı") -> 0 | G34: =COUNTIFS(İhtiyaçlar!$B$2:$B$98,$A34,İhtiyaçlar!$H$2:$H$98,"Bekliyor") -> 0
A35: Toplam | B35: =SUM(B18:B34) -> 97 | C35: =SUM(C18:C34) -> 89 | D35: =SUM(D18:D34) -> 6 | E35: =SUM(E18:E34) -> 2 | F35: =SUM(F18:F34) -> 0 | G35: =SUM(G18:G34) -> 0
A37: Nasıl kullanılır?
A38: 1. 'İhtiyaçlar' sayfasında yalnızca Durum (H), Kanıt (J) ve Not (K) sütunları güncellenir.
A39: 2. Durum açılır listeden seçilir; ✓ sütunu ve bu sayfadaki sayılar formülle otomatik hesaplanır.
A40: 3. Kalıcı güncelleme için aynı değişiklik ihtiyaclar.yaml dosyasına da yazılmalıdır.
A41: 4. 'Bekliyor' = üzerinde çalışılıyor ya da henüz doğrulanamadı; kaldırılan ve birleştirilen ihtiyaçlar 'Değişiklik Geçmişi' sayfasındadır.
A42: 5. Cümle yapısı için 'EARS Kalıpları' sayfasına bakın.

Sheet İhtiyaçlar
A1: ID | B1: Kategori | C1: EARS Tipi | D1: İhtiyaç | E1: Kabul Kriteri | F1: Öncelik | G1: Doğrulama | H1: Durum | I1: ✓ | J1: Kanıt | K1: Not
A2: FR-P1 | B2: Ayrıştırma ve temizleme | C2: Her zaman | D2: Sistem, PDF, HTML, XLSX ve GİB JSON kaynaklarını ortak bir belge modeline dönüştürmelidir. | E2: Dört kaynak türü için ayrıştırıcı aynı Document tipini döndürür. | F2: Zorunlu | G2: Test | H2: Karşılandı | I2: =IF(H2="Karşılandı","✔",IF(H2="Kısmi","◐",IF(H2="Karşılanmadı","✖",""))) -> ✔ | J2: ingestion/parser_registry.py; test_html_parser.py::test_parse_returns_document_with_metadata, test_gib_parser.py::test_gib_articles_parsed, test_xlsx_parser.py::test_one_table_section_per_sheet, test_pdf_text.py::test_extract_pages_reads_fixture_pdf.
A3: FR-P3 | B3: Ayrıştırma ve temizleme | C3: Her zaman | D3: Sistem, çıkarılan metinden sayfa numaralarını, tekrarlayan üstlük/altlıkları ve bozuk karakter kodlamalarını temizlemelidir. | E3: '2/47', 'KANUN VE YÖNETMELİKLER III-8' gibi kalıntılar çıktıda yoktur; metin Unicode NFC biçimindedir; eski Mac Türkçe glifleri onarılır. | F3: Zorunlu | G3: Test | H3: Karşılandı | I3: =IF(H3="Karşılandı","✔",IF(H3="Kısmi","◐",IF(H3="Karşılanmadı","✖",""))) -> ✔ | J3: test_pdf_text.py::test_strips_repeated_header_and_page_numbers, ::test_removes_tiklayiniz_lines; test_normalize.py::test_nfc_composes_decomposed_chars, ::test_repair_mac_turkish_glyphs.
A4: FR-P4 | B4: Ayrıştırma ve temizleme | C4: Her zaman | D4: Sistem, mevzuat belgelerinden kısım, bölüm, madde, fıkra ve bent hiyerarşisini çıkarmalıdır. | E4: Örnek belgelerde madde numaraları, başlıkları ve fıkra/bent etiketleri doğru eşleşir. | F4: Zorunlu | G4: Test | H4: Karşılandı | I4: =IF(H4="Karşılandı","✔",IF(H4="Kısmi","◐",IF(H4="Karşılanmadı","✖",""))) -> ✔ | J4: ingestion/legislation_parser.py; test_legislation_parser.py::test_hierarchy_labels, ::test_bolum_resets_on_new_kisim, ::test_paragraphs_split_on_fikra_and_bent.
A5: FR-P5 | B5: Ayrıştırma ve temizleme | C5: Her zaman | D5: Sistem, değişiklik notlarını madde metninden ayırıp metadata olarak saklamalıdır. | E5: '(Değişik: …YK)' ibareleri embed edilen metinde yer almaz, parça metadata'sında listelenir. | F5: Önemli | G5: Test | H5: Karşılandı | I5: =IF(H5="Karşılandı","✔",IF(H5="Kısmi","◐",IF(H5="Karşılanmadı","✖",""))) -> ✔ | J5: test_legislation_parser.py::test_amendment_notes_moved_to_metadata; test_structural.py::test_amendment_notes_in_metadata_not_text; test_gib_parser.py::test_gib_amendment_note_extracted.
A6: FR-P6 | B6: Ayrıştırma ve temizleme | C6: Her zaman | D6: Sistem, yürürlükten kaldırılmış (mülga) maddeleri indeks dışında bırakmalıdır. | E6: Yalnızca '(Mülga…)' içeren maddeler indekste bulunmaz. | F6: Önemli | G6: Test | H6: Karşılandı | I6: =IF(H6="Karşılandı","✔",IF(H6="Kısmi","◐",IF(H6="Karşılanmadı","✖",""))) -> ✔ | J6: test_legislation_parser.py::test_repealed_article_flagged; test_structural.py::test_repealed_skipped; test_fixed.py::test_repealed_sections_excluded.
A7: FR-P9 | B7: Ayrıştırma ve temizleme | C7: İstenmeyen | D7: Bir PDF'ten metin çıkarılamadığı durumunda, sistem belgeyi ingest raporunda 'taranmış' olarak listelemelidir. | E7: Taranmış ve içeriksiz belgeler indekslenmez, raporda ayrı listelenir. | F7: Önemli | G7: Test | H7: Karşılandı | I7: =IF(H7="Karşılandı","✔",IF(H7="Kısmi","◐",IF(H7="Karşılanmadı","✖",""))) -> ✔ | J7: test_ingest.py::test_scanned_docs_reported_not_indexed; artifacts/ingest_report.json: 3 taranmış PDF, 18 içeriksiz sayfa.
A8: FR-P10 | B8: Ayrıştırma ve temizleme | C8: Her zaman | D8: Sistem, her belgeye kimlik, başlık, program kodu, belge türü, kaynak URL, sürüm tarihi, dil ve SHA-256 metadata alanlarını atamalıdır. | E8: Belge modeli bu alanları içerir; bilinmeyen alanlar açıkça boş (null) tutulur; başlık okunabilir bir belge adıdır. | F8: Zorunlu | G8: Test | H8: Kısmi | I8: =IF(H8="Karşılandı","✔",IF(H8="Kısmi","◐",IF(H8="Karşılanmadı","✖",""))) -> ◐ | J8: domain/document.py; test_document_builder.py::test_skeleton_copies_entry_metadata_and_uses_real_sha, ::test_skeleton_keeps_missing_fields_as_none. | K8: Açık hata: 132 parçada belge başlığı boş ya da 'tıklayınız' (program sayfası bağlantı metninden geliyor); 111 belgede sürüm tarihi yok.
A9: FR-C1 | B9: Parçalama (chunking) | C9: Her zaman | D9: Sistem, sabit pencereli parçalamada parça boyutunun ve örtüşmenin token cinsinden yapılandırılmasına izin vermelidir. | E9: 512 token / 64 örtüşme ile üretilen parçalar bu sınırlara uyar; örtüşme boyuttan küçük olmalıdır. | F9: Zorunlu | G9: Test | H9: Karşılandı | I9: =IF(H9="Karşılandı","✔",IF(H9="Kısmi","◐",IF(H9="Karşılanmadı","✖",""))) -> ✔ | J9: chunking/fixed.py; test_fixed.py::test_windows_respect_size_and_overlap, ::test_rejects_overlap_not_smaller_than_size; v0/v0r: 4.193 parça.
A10: FR-C2 | B10: Parçalama (chunking) | C10: Opsiyonel | D10: Yapı bazlı parçalama etkinleştirildiğinde, sistem her maddeyi, her HTML bölümünü ve her SSS soru-cevap çiftini ayrı bir parça olarak üretmelidir. | E10: Uzunluk eşiğini aşan madde fıkra sınırlarından bölünür, hiçbir fıkra ortadan kesilmez; bir SSS çifti tek parçadadır. | F10: Zorunlu | G10: Test | H10: Karşılandı | I10: =IF(H10="Karşılandı","✔",IF(H10="Kısmi","◐",IF(H10="Karşılanmadı","✖",""))) -> ✔ | J10: chunking/structural.py; test_structural.py::test_each_article_is_one_chunk, ::test_long_article_split_at_paragraph_boundaries, ::test_faq_pair_single_chunk, ::test_html_sections_separate_chunks; v1–v3b: 7.017 parça.
A11: FR-C6 | B11: Parçalama (chunking) | C11: Opsiyonel | D11: Bağlam başlığı seçeneği etkinleştirildiğinde, sistem her parçanın embed edilen metninin başına belge ve hiyerarşi bilgisini eklemelidir. | E11: embed_text 'Belge › Bölüm › Madde N – Başlık' satırıyla başlar; kullanıcıya gösterilen text değişmez. | F11: Zorunlu | G11: Test | H11: Karşılandı | I11: =IF(H11="Karşılandı","✔",IF(H11="Kısmi","◐",IF(H11="Karşılanmadı","✖",""))) -> ✔ | J11: chunking/context_header.py; test_structural.py::test_embed_text_starts_with_doc_and_hierarchy, ::test_text_unchanged_when_header_on, ::test_same_title_different_program_yields_different_embed_text.
A12: FR-I2 | B12: İndeksleme | C12: Olay | D12: Corpus'ta bir belge eklendiğinde, değiştiğinde veya silindiğinde, sistem yalnızca o belgenin dense ve BM25 indeks kayıtlarını güncellemelidir. | E12: Diğer belgelerin embedding'leri yeniden hesaplanmaz; silinen belgenin parçaları aramada dönmez; ikinci ingest hiçbir şey değiştirmez. | F12: Zorunlu | G12: Test | H12: Karşılandı | I12: =IF(H12="Karşılandı","✔",IF(H12="Kısmi","◐",IF(H12="Karşılanmadı","✖",""))) -> ✔ | J12: indexing/sync.py; test_sync.py::test_apply_only_embeds_changed_docs, ::test_apply_update_replaces_chunks, ::test_apply_remove_deletes; test_ingest.py::test_ingest_removes_deleted_doc_from_both_indexes.
A13: FR-X9 | B13: İndeksleme | C13: Durum | D13: Bir belgenin içeriği ve işlem ayarları değişmemişken, sistem ayrıştırma, parçalama ve embedding sonuçlarını önbellekten yeniden kullanmalıdır. | E13: İkinci ingest ayrıştırma ve embedding adımlarını atlar; önbellek model adına göre ayrıdır. | F13: Zorunlu | G13: Test | H13: Karşılandı | I13: =IF(H13="Karşılandı","✔",IF(H13="Kısmi","◐",IF(H13="Karşılanmadı","✖",""))) -> ✔ | J13: test_ingest.py::test_second_ingest_is_noop_and_skips_parse_and_embed, ::test_full_flag_rebuilds_everything_from_the_caches; test_embedding_cache.py::test_lookup_is_per_model; ölçüm: önbellekli ingest 23 s (7.017 parça).
A14: FR-R1 | B14: Arama ve yeniden sıralama | C14: Her zaman | D14: Sistem, arama yönteminin dense, BM25 veya hibrit olarak yapılandırmayla seçilmesine izin vermelidir. | E14: retriever.mode değiştirilerek aynı corpus üzerinde üç yöntem çalışır. | F14: Zorunlu | G14: Test | H14: Karşılandı | I14: =IF(H14="Karşılandı","✔",IF(H14="Kısmi","◐",IF(H14="Karşılanmadı","✖",""))) -> ✔ | J14: test_factory.py::test_build_retriever_by_mode_uses_config_collection; test_dense.py, test_bm25.py, test_hybrid.py; configs/experiments/v0–v3b.yaml.
A15: FR-R3 | B15: Arama ve yeniden sıralama | C15: Opsiyonel | D15: Kök bulma seçeneği etkinleştirildiğinde, sistem BM25 belirteçlerine Türkçe kök bulma uygulamalıdır. | E15: 'projelerin' ve 'projeler' aynı köke iner; Türkçe küçük harf dönüşümü (İ→i, I→ı) her zaman uygulanır; sayılar ve program kodları köklenmez. | F15: Önemli | G15: Test | H15: Karşılandı | I15: =IF(H15="Karşılandı","✔",IF(H15="Kısmi","◐",IF(H15="Karşılanmadı","✖",""))) -> ✔ | J15: retrieval/turkish.py; test_turkish.py::test_stemming_merges_plural_forms, ::test_no_stemming_option, ::test_turkish_lower_dotted_and_dotless_i, ::test_numbers_are_not_stemmed.
A16: FR-R4 | B16: Arama ve yeniden sıralama | C16: Opsiyonel | D16: Hibrit arama etkinleştirildiğinde, sistem dense ve BM25 sonuç sıralarını Reciprocal Rank Fusion ile birleştirmelidir. | E16: RRF projenin kendi kodundadır; k varsayılan 60 ve yapılandırılabilir; bilinen örnekte doğru sıralama çıkar. | F16: Zorunlu | G16: Test | H16: Karşılandı | I16: =IF(H16="Karşılandı","✔",IF(H16="Kısmi","◐",IF(H16="Karşılanmadı","✖",""))) -> ✔ | J16: retrieval/rrf.py; test_rrf.py::test_rrf_known_example; test_hybrid.py::test_rrf_k_is_used; v1→v2 Recall@5 0,439→0,543.
A17: FR-R5 | B17: Arama ve yeniden sıralama | C17: Opsiyonel | D17: Bir soruyla birlikte metadata filtresi verildiğinde, sistem sonuçları program kodu ve belge türüne göre süzmelidir. | E17: program_kodu=1507 filtresiyle yalnızca 1507 belgeleri döner; filtre REST API ve `rag ask` ile verilir. | F17: Önemli | G17: Test | H17: Karşılandı | I17: =IF(H17="Karşılandı","✔",IF(H17="Kısmi","◐",IF(H17="Karşılanmadı","✖",""))) -> ✔ | J17: test_filters.py::test_apply_filters_program_and_type; test_api.py::test_ask_forwards_filters_and_config; test_cli.py::test_ask_cli_program_and_type_become_filters. | K17: Web arayüzündeki filtreler sohbet sayfasına geçişte kaldırıldı.
A18: FR-RR1 | B18: Arama ve yeniden sıralama | C18: Opsiyonel | D18: Yeniden sıralayıcı etkinleştirildiğinde, sistem ilk aşama adaylarını cross-encoder ile yeniden sıralayıp en iyi n parçayı döndürmelidir. | E18: Varsayılan 30 aday → 5 sonuç; yeniden sıralama skoru sonuçla birlikte döner. | F18: Zorunlu | G18: Test | H18: Karşılandı | I18: =IF(H18="Karşılandı","✔",IF(H18="Kısmi","◐",IF(H18="Karşılanmadı","✖",""))) -> ✔ | J18: reranking/cross_encoder.py; test_cross_encoder.py::test_rerank_with_returns_top_n_sorted; test_pipeline.py::test_reranker_used_when_present_and_scores_kept; v2→v3 Recall@5 0,543→0,699.
A19: FR-G3 | B19: Cevap üretimi ve atıf | C19: Her zaman | D19: Sistem, cevaptaki her atıfı belge adı, madde veya sayfa bilgisi ve kaynak bağlantısıyla birlikte sunmalıdır. | E19: Cevaptaki [n] işaretleri numaralı kaynaklara karşılık gelir; her atıf bu üç bilgiyi taşır. | F19: Zorunlu | G19: Test | H19: Karşılandı | I19: =IF(H19="Karşılandı","✔",IF(H19="Kısmi","◐",IF(H19="Karşılanmadı","✖",""))) -> ✔ | J19: test_generator.py::test_citations_have_title_location_url; test_prompts.py::test_sources_numbered_from_one; test_pipeline.py::test_valid_answer_has_citations_sources_and_disclaimer.
A20: FR-G4 | B20: Cevap üretimi ve atıf | C20: Her zaman | D20: Sistem, cevap üreten dil modelinin yapılandırmayla Ollama üzerinden yerel bir model veya OpenAI uyumlu bir API (ör. OpenRouter, Groq, Hugging Face Inference Providers) olarak seçilmesine izin vermelidir. | E20: Kod değişmeden yalnız llm.provider ve llm.model değiştirilir: ollama (varsayılan, yerel qwen3:4b) veya openai_compat (/chat/completions; adres LLM_BASE_URL, anahtar LLM_API_KEY ortam değişkeninden). Aynı alanla anthropic (Claude API) ve transformers (model süreç içinde; Hugging Face Space) da seçilebilir. | F20: Zorunlu | G20: Test | H20: Karşılandı | I20: =IF(H20="Karşılandı","✔",IF(H20="Kısmi","◐",IF(H20="Karşılanmadı","✖",""))) -> ✔ | J20: config.py LlmConfig, OpenAICompatConfig; factory.py build_llm; adapters/ollama_llm.py, openai_compat_llm.py, anthropic_llm.py, transformers_llm.py; test_factory.py::test_provider_switch_by_config_only; test_openai_compat_llm.py::test_factory_builds_it_from_config, ::test_api_key_read_from_the_named_environment_variable, ::test_rejected_json_schema_falls_back_to_json_object_and_remembers; test_ollama_llm.py::test_request_body_has_think_false_format_and_temperature_zero; test_transformers_llm.py::test_factory_builds_it_from_config; test_anthropic_llm.py. Ollama yolu altı deney koşusunda gerçek olarak kullanıldı; transformers yolu canlı Space'te çalışıyor (FR-HF1). | K20: OpenAI uyumlu bağdaştırıcı yalnız birim testlerinde, sahte HTTP taşıyıcısıyla ve Ollama'nın /v1 uç noktasıyla aynı istek/yanıt biçiminde doğrulandı; gerçek ücretli bir sağlayıcıyla (OpenRouter, Groq, Hugging Face) denenmedi. Anthropic bağdaştırıcısı da sahte SDK ile test edildi.
A21: FR-G7 | B21: Cevap üretimi ve atıf | C21: Her zaman | D21: Sistem, değerlendirmede kullanılan hakem modelinin sağlayıcısının ve modelinin cevap modelinden bağımsız olarak yapılandırmayla seçilmesine izin vermelidir. | E21: eval.judge.provider ve eval.judge.model ayrı ayarlanır (ollama, openai_compat, anthropic, transformers); bağlantı ayarları llm bölümünden gelir; hakem sıcaklığı 0'dır; varsayılan yerel Ollama qwen3:4b'dir. | F21: Önemli | G21: Test | H21: Karşılandı | I21: =IF(H21="Karşılandı","✔",IF(H21="Kısmi","◐",IF(H21="Karşılanmadı","✖",""))) -> ✔ | J21: config.py JudgeConfig; interfaces/cli.py _judge_llm_config; test_cli_run.py::test_run_cli_judge_is_local_and_deterministic, ::test_run_cli_warns_when_an_api_provider_is_configured. | K21: Hakem isteğe bağlıdır (FR-E34); raporlanan cevap metrikleri hakemden değil Claude (Opus) incelemesinden gelir.
A22: FR-G5 | B22: Cevap üretimi ve atıf | C22: Her zaman | D22: Sistem, her cevabı bilginin resmî görüş olmadığını belirten bir uyarıyla birlikte sunmalıdır. | E22: Uyarı API cevabının uyari alanında ve arayüzde bir kez görünür; cevap metninde tekrar edilmez. | F22: Önemli | G22: Test | H22: Karşılandı | I22: =IF(H22="Karşılandı","✔",IF(H22="Kısmi","◐",IF(H22="Karşılanmadı","✖",""))) -> ✔ | J22: test_pipeline.py::test_disclaimer_is_given_once_in_its_own_field; test_pages.py::test_disclaimer_is_shown_once_on_the_page; test_api.py::test_ask_returns_answer_with_citations_and_disclaimer.
A23: FR-G6 | B23: Cevap üretimi ve atıf | C23: Her zaman | D23: Sistem, kaynak metinleri dil modeline talimat olarak değil veri olarak işaretleyerek vermelidir. | E23: Sistem istemi kaynaklardaki talimatların uygulanmayacağını söyler; kaynaklar ve soru ayrı etiketler içindedir. | F23: Önemli | G23: Test | H23: Karşılandı | I23: =IF(H23="Karşılandı","✔",IF(H23="Kısmi","◐",IF(H23="Karşılanmadı","✖",""))) -> ✔ | J23: generation/prompts.py; test_prompts.py::test_system_prompt_treats_sources_as_data_not_instructions, ::test_user_prompt_delimits_data_and_question, ::test_faq_question_text_stays_inside_source_tags.
A24: FR-GR1 | B24: Güvenlik önlemleri (guardrail) | C24: İstenmeyen | D24: En yüksek arama skoru yapılandırılmış eşiğin altında kaldığı durumunda, sistem dil modelini çağırmadan 'bilgi bulunamadı' cevabı döndürmelidir. | E24: Eşik altı soruda LLM çağrı sayısı 0'dır; eşikler skor türü başına yapılandırma dosyasından okunur. | F24: Zorunlu | G24: Test | H24: Karşılandı | I24: =IF(H24="Karşılandı","✔",IF(H24="Kısmi","◐",IF(H24="Karşılanmadı","✖",""))) -> ✔ | J24: guardrails/gate.py; test_pipeline.py::test_below_threshold_returns_bilgi_bulunamadi_with_no_llm_call_and_no_sources; test_gate.py::test_thresholds_from_config_not_constants.
A25: FR-GR2 | B25: Güvenlik önlemleri (guardrail) | C25: İstenmeyen | D25: Sistem bir soruyu reddettiği durumunda, sistem cevapla birlikte hiçbir kaynak göstermemelidir. | E25: Bilgi bulunamadı, kapsam dışı ve atıf reddi cevaplarında kaynak ve atıf listesi boştur. | F25: Zorunlu | G25: Test | H25: Karşılandı | I25: =IF(H25="Karşılandı","✔",IF(H25="Kısmi","◐",IF(H25="Karşılanmadı","✖",""))) -> ✔ | J25: test_api.py::test_refusals_return_no_sources; test_pipeline.py::test_llm_not_answerable_returns_no_sources; test_pages.py::test_not_found_is_a_reply_without_sources.
A26: FR-GR3 | B26: Güvenlik önlemleri (guardrail) | C26: İstenmeyen | D26: Dil modeli atıfsız bir cevap veya verilmemiş bir kaynağa atıf ürettiği durumunda, sistem cevabı 'bilgi bulunamadı' cevabına dönüştürmelidir. | E26: Uydurma atıflı ve atıfsız sahte LLM çıktıları reddedilir. | F26: Zorunlu | G26: Test | H26: Karşılandı | I26: =IF(H26="Karşılandı","✔",IF(H26="Kısmi","◐",IF(H26="Karşılanmadı","✖",""))) -> ✔ | J26: guardrails/citations.py; test_pipeline.py::test_llm_answer_with_fabricated_citation_is_rejected_to_bilgi_bulunamadi, ::test_uncited_answer_is_refused; test_citations.py.
A27: FR-GR4 | B27: Güvenlik önlemleri (guardrail) | C27: İstenmeyen | D27: Soru TÜBİTAK destek programları ve Ar-Ge mevzuatı kapsamı dışında olduğu durumunda, sistem soruyu kapsam dışı olduğunu belirterek reddetmelidir. | E27: Kapsam dışı sorularda arama yapılmaz; test setindeki kapsam dışı soruların ret oranı raporlanır. | F27: Zorunlu | G27: Test | H27: Karşılandı | I27: =IF(H27="Karşılandı","✔",IF(H27="Kısmi","◐",IF(H27="Karşılanmadı","✖",""))) -> ✔ | J27: guardrails/scope.py; test_pipeline.py::test_out_of_scope_returns_kapsam_disi_without_retrieval_or_sources; 6 koşunun hepsinde kapsam dışı ret oranı 1,0 (docs/sample-reports/*.metrics.json). | K27: v3b'de 2 kapsam içi soru yanlışlıkla kapsam dışı sayıldı (counts.scope_false_rejections).
A28: FR-GR5 | B28: Güvenlik önlemleri (guardrail) | C28: Durum | D28: Soru kaynaklarla yalnızca kısmen cevaplanabilirken, sistem cevaplanamayan kısmı cevapta açıkça belirtmelidir. | E28: Model 'eksik kısım' bildirdiğinde bu kısım cevaba eklenir. | F28: Önemli | G28: Test | H28: Karşılandı | I28: =IF(H28="Karşılandı","✔",IF(H28="Kısmi","◐",IF(H28="Karşılanmadı","✖",""))) -> ✔ | J28: guardrails/postprocess.py; test_pipeline.py::test_missing_part_appended; test_postprocess.py::test_missing_part_appended. | K28: Mekanizma test edildi; etkisi ayrı bir metrikle ölçülmüyor.
A29: FR-GR6 | B29: Güvenlik önlemleri (guardrail) | C29: Durum | D29: Atıf yapılan kaynak bilgiyi çağrı duyurusuna yönlendirirken, sistem cevapta ilgili duyuru sayfasının bağlantısını vermelidir. | E29: 'çağrı duyurusunda belirtilir' içeren kaynakta cevap program sayfası URL'sini içerir. | F29: Önemli | G29: Test | H29: Karşılandı | I29: =IF(H29="Karşılandı","✔",IF(H29="Kısmi","◐",IF(H29="Karşılanmadı","✖",""))) -> ✔ | J29: test_pipeline.py::test_announcement_link_added_when_cited_source_defers_to_call, ::test_announcement_link_prefers_cited_program_page, ::test_no_announcement_link_from_uncited_source.
A30: FR-GR7 | B30: Güvenlik önlemleri (guardrail) | C30: Durum | D30: Aynı konuda farklı sürüm tarihli kaynaklar bulunurken, sistem cevabı en güncel sürüm tarihli kaynağa dayandırmalıdır. | E30: Test setindeki sürüm sorularında cevap en güncel değeri verir. | F30: Önemli | G30: Test | H30: Kısmi | I30: =IF(H30="Karşılandı","✔",IF(H30="Kısmi","◐",IF(H30="Karşılanmadı","✖",""))) -> ◐ | J30: generation/prompts.py en yeni sürümü öne alır (test_prompts.py::test_newer_version_listed_first_same_type_program); v3b sürüm sorularında doğruluk 0,9 (qwen3:4b hakem). | K30: Claude incelemesinde sürüm sorularında eski değeri seçme hataları görüldü (docs/sample-reports/claude-degerlendirme.md); 111 belgede sürüm tarihi yok.
A31: FR-GR8 | B31: Güvenlik önlemleri (guardrail) | C31: Durum | D31: Program belirtilmeyen bir sorunun cevabı programa göre değişirken, sistem cevabı programlara göre ayrıştırarak vermelidir. | E31: Test setindeki belirsiz sorularda cevap programları ayrı ayrı adlandırır (programs_split_rate). | F31: Önemli | G31: Test | H31: Karşılanmadı | I31: =IF(H31="Karşılandı","✔",IF(H31="Kısmi","◐",IF(H31="Karşılanmadı","✖",""))) -> ✖ | J31: Kural istemde var (generation/prompts.py, kural 7) ama 6 koşunun hepsinde programs_split_rate 0,0; v3b belirsiz sorularda doğruluk 0,6. | K31: Küçük LLM tek programın değerini genel kural gibi veriyor (claude-degerlendirme.md).
A32: FR-GR11 | B32: Güvenlik önlemleri (guardrail) | C32: İstenmeyen | D32: Cevap kaynaklarda geçmeyen bir sayı içerdiği durumunda, sistem o cümleyi cevaptan çıkarmalıdır. | E32: number_check: strip varsayılandır; sayı yalnız atıf yapılmamış bir kaynakta geçiyorsa atıf onarılır; hiçbir cümle kalmazsa cevap reddedilir. | F32: Zorunlu | G32: Test | H32: Kısmi | I32: =IF(H32="Karşılandı","✔",IF(H32="Kısmi","◐",IF(H32="Karşılanmadı","✖",""))) -> ◐ | J32: guardrails/numbers.py; test_numbers.py::test_fabricated_duration_sentence_is_stripped, ::test_number_in_uncited_prompt_source_repairs_the_citation; test_pipeline.py::test_number_guardrail_strip_drops_the_ungrounded_sentence. | K32: Bilinen açıklar: q083'te uydurma tutar denetimden geçiyor; sorudaki sayı kanıt sayılabiliyor (test_question_grounding_security.py, strict xfail); 'yüzde doksan beşi' 90 okunuyordu, düzeltildi (test_numbers.py::test_suffix_on_the_last_number_word_keeps_the_whole_number).
A33: FR-E1 | B33: Test seti | C33: Her zaman | D33: Test seti, TÜBİTAK başvuru süreçleri ve mevzuatı hakkında en az 100 soru içermelidir. | E33: Soru türleri: tek belgeli, çok belgeli, sürüm ve belirsiz (cevaplanmalı); cevabı corpus'ta olmayan ve kapsam dışı (reddedilmeli). eval/testset_v1.jsonl şema doğrulamasından geçer. | F33: Zorunlu | G33: Test | H33: Karşılandı | I33: =IF(H33="Karşılandı","✔",IF(H33="Kısmi","◐",IF(H33="Karşılanmadı","✖",""))) -> ✔ | J33: eval/testset_v1.jsonl: 104 soru = 43 tek belgeli + 16 çok belgeli + 10 sürüm + 10 belirsiz + 15 cevapsız + 10 kapsam dışı; 32 program kodu; test_testset.py::test_repo_testset_is_valid_and_distributed, ::test_type_distribution.
A34: FR-E3 | B34: Test seti | C34: Her zaman | D34: Test seti, corpus'tan cevaplanması gereken tek belgeli ve çok belgeli sorular içermelidir. | E34: Çok belgeli sorunun cevabı en az iki belgenin birleşimini gerektirir ve kanıt alıntıları en az iki farklı belgeden gelir. | F34: Zorunlu | G34: Analiz | H34: Karşılandı | I34: =IF(H34="Karşılandı","✔",IF(H34="Kısmi","◐",IF(H34="Karşılanmadı","✖",""))) -> ✔ | J34: 43 tek belgeli + 16 çok belgeli soru (eval/README.md, tür dağılımı); test_testset.py::test_validate_multi_doc_types_need_two_documents.
A35: FR-E9 | B35: Test seti | C35: Her zaman | D35: Test seti, sistemin reddetmesi gereken kapsam dışı ve cevabı corpus'ta bulunmayan sorular içermelidir. | E35: Cevabı olmayan sorular corpus'ta tek tek aranarak doğrulanır; kapsam dışı sorular TÜBİTAK ve Ar-Ge ile ilgisizdir. | F35: Zorunlu | G35: Analiz | H35: Karşılandı | I35: =IF(H35="Karşılandı","✔",IF(H35="Kısmi","◐",IF(H35="Karşılanmadı","✖",""))) -> ✔ | J35: 15 cevapsız + 10 kapsam dışı soru (eval/README.md, 'Cevapsız soruların tasarımı').
A36: FR-E11 | B36: Test seti | C36: Her zaman | D36: Test seti, program belirtilmeden sorulan ve cevabı programa göre değişen belirsiz sorular içermelidir. | E36: Beklenen cevap programları ayrı ayrı verir; kanıt alıntıları en az iki belgeden gelir. | F36: Önemli | G36: Analiz | H36: Karşılandı | I36: =IF(H36="Karşılandı","✔",IF(H36="Kısmi","◐",IF(H36="Karşılanmadı","✖",""))) -> ✔ | J36: 10 belirsiz soru (eval/README.md, tür dağılımı); test_testset.py::test_validate_multi_doc_types_need_two_documents.
A37: FR-E12 | B37: Test seti | C37: Her zaman | D37: Test seti, eski ve yeni değeri bulunan bilgilere ilişkin sürüm soruları içermelidir. | E37: Beklenen cevap ve beklenen belgeler en güncel kaynağı esas alır; eski değer beklenen cevapta veya notta belirtilir. | F37: Önemli | G37: Analiz | H37: Karşılandı | I37: =IF(H37="Karşılandı","✔",IF(H37="Kısmi","◐",IF(H37="Karşılanmadı","✖",""))) -> ✔ | J37: 10 sürüm sorusu (eval/README.md, tür dağılımı ve 'surum sözleşmesi'). | K37: 10 sorudan 4'ü corpus içinde gerçek bir eski/yeni değer çatışmasıdır; diğer 6'sı tarihli veya çağrıya bağlı değerlerdir.
A38: FR-E16 | B38: Test seti | C38: Her zaman | D38: Test seti, her sorunun cevaplanması mı yoksa reddedilmesi mi gerektiğini belirtmelidir. | E38: Soru türü bunu belirler: tek belgeli, çok belgeli, sürüm ve belirsiz sorular cevaplanmalı (79); cevapsız ve kapsam dışı sorular reddedilmeli (25). Reddedilmesi gereken soruda beklenen cevap 'bilgi bulunamadı' veya 'kapsam dışı'dır, kanıt alıntısı ve beklenen belge yoktur. | F38: Zorunlu | G38: Test | H38: Karşılandı | I38: =IF(H38="Karşılandı","✔",IF(H38="Kısmi","◐",IF(H38="Karşılanmadı","✖",""))) -> ✔ | J38: evaluation/testset.py ANSWERABLE, evaluation/metrics.py UNANSWERABLE; test_testset.py::test_validate_unanswerable_expected_answer_text, ::test_validate_rejects_quotes_for_unanswerable.
A39: FR-E22 | B39: Test seti | C39: Her zaman | D39: Test setindeki her soru, kısa bir beklenen cevap içermelidir. | E39: Beklenen cevap cevabın doğruluğunu değerlendirmede referans olarak kullanılır; beklenen sayılar beklenen cevapta tam sayı olarak geçer. | F39: Zorunlu | G39: Test | H39: Karşılandı | I39: =IF(H39="Karşılandı","✔",IF(H39="Kısmi","◐",IF(H39="Karşılanmadı","✖",""))) -> ✔ | J39: domain/evaluation.py TestQuestion.beklenen_cevap; test_testset.py::test_validate_expected_numbers_appear_in_answer, ::test_repo_testset_is_valid_and_distributed.
A40: FR-E13 | B40: Test seti | C40: Her zaman | D40: Test setindeki her cevaplanabilir soru, corpus metninde birebir geçen 1–3 kanıt alıntısı içermelidir. | E40: Her alıntı beklenen belgenin ayrıştırılmış metninde bulunur; büyük/küçük harf ve boşluk farkı dışında kelimeler değişmez. | F40: Zorunlu | G40: Test | H40: Karşılandı | I40: =IF(H40="Karşılandı","✔",IF(H40="Kısmi","◐",IF(H40="Karşılanmadı","✖",""))) -> ✔ | J40: 117 alıntı: 48 soruda 1, 24 soruda 2, 7 soruda 3 alıntı; test_testset.py::test_validate_requires_quotes_for_answerable, ::test_validate_limits_quote_count, ::test_repo_testset_quotes_match_parsed_corpus.
...

Sheet EARS Kalıpları
A1: Tip | B1: Kalıp | C1: Örnek
A2: Her zaman | B2: <Özne>, <nesne> <eylem>-malıdır/-melidir. | C2: Web arayüzü, her cevabın altında yalnızca o cevapta atıf yapılan kaynakları numaralı olarak listelemelidir.
A3: Olay | B3: <Olay> -dığında/-diğinde, <özne> <eylem>-malıdır. | C3: Corpus'ta bir belge eklendiğinde, değiştiğinde veya silindiğinde, sistem yalnızca o belgenin dense ve BM25 indeks kayıtlarını güncellemelidir.
A4: Durum | B4: <Durum> iken, <özne> <eylem>-malıdır. | C4: Cihaz ayarı 'auto' iken, sistem modelleri uyumlu bir GPU varsa GPU'da, yoksa CPU'da çalıştırmalıdır.
A5: İstenmeyen | B5: <İstenmeyen durum> durumunda, <özne> <eylem>-malıdır. | C5: Soru TÜBİTAK destek programları ve Ar-Ge mevzuatı kapsamı dışında olduğu durumunda, sistem soruyu kapsam dışı olduğunu belirterek reddetmelidir.
A6: Opsiyonel | B6: <Özellik> etkinleştirildiğinde, <özne> <eylem>-malıdır. | C6: Kök bulma seçeneği etkinleştirildiğinde, sistem BM25 belirteçlerine Türkçe kök bulma uygulamalıdır.
A8: Kurallar
A9: • Her ihtiyaç tek bir yükümlülük içerir (tek '-malıdır/-melidir').
A10: • Özne açıkça yazılır: Sistem, Corpus, Test seti, Web arayüzü, REST API, Komut satırı arayüzü, Değerlendirme modülü, Cevap değerlendirmesi, Rapor üretici, Docker paketi, Barındırılan sürüm…
A11: • İhtiyaç aracı kullanan kişinin (soru soran, RAG öğrenen, aracı çalıştıran, katkıda bulunan) bakışıyla yazılır; geliştirme süreci ihtiyaç değildir.
A12: • İhtiyaç 'ne' yapılacağını söyler; 'nasıl' yapılacağı kabul kriterinde ve tasarımda yer alır.
A13: • Her ihtiyaç bir doğrulama yöntemiyle (Test, Gösterim, İnceleme, Analiz) ve somut bir kanıtla eşleşir.

Sheet Sözlük
A1: Terim | B1: Açıklama
A2: RAG | B2: Retrieval-Augmented Generation: dil modelinin cevabı, aranan belge parçalarına dayanarak üretmesi.
A3: Parça (chunk) | B3: Belgenin arama ve embedding için bölündüğü metin birimi.
A4: Embedding | B4: Metnin anlamını temsil eden sayısal vektör.
A5: Dense arama | B5: Sorgu ve parça vektörleri arasındaki benzerliğe dayalı anlamsal arama.
A6: BM25 | B6: Kelime eşleşmesi ve kelime nadirliğine dayalı klasik (sparse) arama algoritması.
A7: Hibrit arama | B7: Dense ve BM25 sonuçlarının birleştirilmesi.
A8: RRF | B8: Reciprocal Rank Fusion: sıralamaları 1/(k+sıra) ile birleştiren yöntem (k=60).
A9: Yeniden sıralayıcı | B9: Aday parçaları soru ile birlikte okuyup yeniden puanlayan cross-encoder model.
A10: Guardrail | B10: Uydurma cevabı ve kapsam dışı kullanımı engelleyen güvenlik önlemi.
A11: Kanıt alıntısı | B11: Test setinde doğru cevabın geçtiği birebir metin parçası; arama isabetini ölçmek için kullanılır.
A12: Recall@k | B12: Doğru kanıtın ilk k sonuç içinde bulunduğu soruların oranı.
... A19: Artımlı indeksleme | B19: Yalnızca yeni, değişen veya silinen belgelerin indekste güncellenmesi.

Sheet Değişiklik Geçmişi
A1: Tarih | B1: Sürüm | C1: Yazan | D1: Değişiklik
A2: 2026-10-15 | B2: 0.1 | C2: Claude | D2: İlk taslak (Markdown tabloları).
A3: 2026-10-15 | B3: 1.0 | C3: Claude | D3: İhtiyaçlar EARS kalıbına göre tek yükümlülüklü cümlelere dönüştürüldü; tek kaynak YAML + Excel takip matrisi.
A4: 2026-10-19 | B4: 2.0 | C4: Claude | D4: İhtiyaçlar ürün ve kullanıcı bakışıyla yeniden yazıldı (109 → 94). Geliştirme sürecine ve yapay zekâ ajanının çalışma biçimine dair maddeler çıkarıldı; corpus kapsamı, test seti (cevaplanacak, reddedilecek, belirsiz ve sürüm soruları) ve arama ile cevap değerlendirmesi ayrı ihtiyaçlar olarak yazıldı; arayüz güncel ürüne (sohbet sayfası + Hakkında) göre güncellendi. Her ihtiyacın durumu ve kanıtı kod, testler ve ölçülen sonuçlarla doğrulandı.
A5: 2026-10-19 | B5: 2.0 | C5: Claude | D5: Kaldırılan süreç maddeleri: SR-1 (aşama başına geliştirme günlüğü), SR-2 (her aşamada inceleme ajanı), SR-3 (aşama başına commit), SR-4 (proje sonunda karşılama matrisi), FR-U5'in eski hâli (taste-skill kuralları, gerekçe günlükte; yerel varlıklar ihtiyacına dönüştü), NFR-LANG1'deki geliştirme günlüğü dili, NFR-LANG2 (İngilizce tanımlayıcılar), NFR-CLEAN3 (fabrika katmanı), NFR-TEST4 (entegrasyon işareti), FR-CLI1'deki eval-gen komutu (uygulanmadı; test seti elle yazıldı).
A6: 2026-10-19 | B6: 2.0 | C6: Claude | D6: Ürün değiştiği için kaldırılan/dönüşen: FR-U4 (Deneyler sayfası kaldırıldı; raporlar REST API ve docs/sample-reports üzerinden), FR-U3 (ingest düğmeli Belgeler sayfası → Hakkında sayfası), FR-U2 (kaynak paneli → sohbet akışı), FR-U6 (Streamlit sürümü 'Barındırılan sürüm' kategorisine taşındı), FR-C5 (kılavuzların başlık/paragraf bölünmesi; tasarım ayrıntısı, test_guide_parser.py ile korunuyor).
A7: 2026-10-19 | B7: 2.0 | C7: Claude | D7: Birleştirilen: FR-D2 → FR-D1/FR-D3; FR-P2 → FR-P3; FR-P7, FR-C3, FR-C4 → FR-C2; FR-P8, FR-C7, FR-G1, FR-G2 → FR-G3; FR-I1, FR-I3, FR-I4, FR-I6 → FR-I2; FR-I5 → FR-X9; FR-R2 → FR-R3; FR-RR2, FR-GR9 → FR-GR1; FR-E2 → FR-E13; FR-E8 → FR-X3; FR-E7 → FR-E7, FR-E17, FR-E18, FR-E19; FR-X2, FR-X10 → FR-X1; FR-X4…FR-X7 → FR-X3; NFR-REPRO2 → NFR-REPRO1; FR-A2 → FR-A1; FR-A3 → FR-A4; FR-U1 → FR-U5; NFR-DOCKER2, NFR-DOCKER3 → NFR-DOCKER1; NFR-HW3 → NFR-HW1; NFR-MOD1 → NFR-MOD2; NFR-CLEAN1, NFR-CLEAN2 → NFR-CI1.
A8: 2026-10-21 | B8: 2.1 | C8: Claude | D8: Streamlit sürümü kaldırıldı: FR-U6 Kapsam dışı; FR-HF1 barındırılan Gradio + ZeroGPU Space'e göre yeniden yazıldı; NFR-MOD3'te Streamlit yerine Gradio. NFR-DOCKER5: hazır indeks paketi varsayılan olarak Hugging Face veri setinden indirilir.
A9: 2026-10-19 | B9: 2.0 | C9: Claude | D9: Yeni: FR-D6, FR-D7, FR-D8 (corpus kapsamı), FR-D10 (site erişim kuralları), FR-D12 (sürümler), FR-G6, FR-GR11, FR-E9, FR-E11, FR-E12, FR-E13, FR-E14 (test seti), FR-E17…FR-E21 (cevap metrikleri), FR-U7, FR-U8, FR-U11, FR-HF1, FR-A5, FR-CLI2, FR-CLI3, NFR-DOCKER4, NFR-DOCKER5, NFR-DOCKER6, NFR-SEC1.
A10: 2026-10-21 | B10: 2.2 | C10: Claude | D10: Corpus ve veri edinimi kategorisi kaldırıldı (FR-D6, FR-D7, FR-D8, FR-D1, FR-D3, FR-D10, FR-D4, FR-D5, FR-D12). Ürün, belgelerin elde olduğu ve indekslendiği noktadan başlar; belgeleri bulmak ve indirmek ürün ihtiyacı değil, corpus hazırlığıdır (rehber §1). Ayrıştırma ve temizleme ihtiyaçları kalır.
A11: 2026-10-21 | B11: 2.3 | C11: Claude | D11: Kaldırılan: NFR-REPRO1 (aynı girdilerle aynı arama metrikleri; ürün sahibi gerekli görmedi), FR-U6 (Streamlit sürümü; Streamlit artık yok, madde tamamen silindi), NFR-CI1 (CI hattı; projede kullanılan bir CI hattı yok, .github/workflows/ci.yml dosyası duruyor). Geliştirme planı (docs/plan.md, docs/plan/) depodan kaldırıldı.
A12: 2026-10-21 | B12: 2.3 | C12: Claude | D12: Barındırılan sürüm üç ihtiyaca bölündü: FR-HF1 (Gradio + ZeroGPU, Qwen3 4B, embedding ve reranker Space GPU'sunda), FR-HF2 (Qdrant ve Ollama olmadan hazır NumPy indeksi), FR-HF3 (web arayüzüyle aynı sohbet, yapılandırma seçici ve numaralı kaynaklar). FR-G4 iki ihtiyaca bölündü: FR-G4 (cevap modeli: Ollama ile yerel model veya OpenAI uyumlu API; ayrıca Anthropic ve transformers) ve FR-G7 (hakem modeli, cevap modelinden bağımsız ve isteğe bağlı).
A13: 2026-10-21 | B13: 2.3 | C13: Claude | D13: Test ihtiyaçları ayrıntılandırıldı. Test seti: FR-E1 tür dağılımını sayar; yeni FR-E16 (cevaplanmalı/reddedilmeli etiketi), FR-E22 (beklenen cevap), FR-E23 (beklenen belgeler), FR-E24 (beklenen sayılar); FR-E4 sentetik üretimi açıkça yazar. Arama testi: FR-E6 Recall@5/@10 ve MRR'ye daraltıldı; yeni FR-E26 (belge isabeti), FR-E27 (soru türüne göre), FR-E29 (kanıtın ilk sırası), FR-E30 (ilk sıra dağılımı). Cevap testi: FR-E7, FR-E17, FR-E18, FR-E19 Claude (Opus) incelemesine göre yeniden yazıldı; yeni FR-E31 (gereksiz retin aşaması), FR-E32 (uydurma cevaplar), FR-E33 (atıf kesinliği), FR-E34 (isteğe bağlı otomatik hakem).
