Workbook

Sheet Özet
A1: TÜBİTAK Mevzuatı RAG — Testler
A2: Oluşturma: 2026-10-27 · Koşular: v0_20261016-004903, v0r_20261016-005933, v1_20261016-011056, v2_20261016-012233, v3_20261016-013413, v3b_20261016-014819
A3: Kaynaklar: eval/testset_v1.jsonl, artifacts/runs/*/per_question.jsonl, artifacts/judge/*_claude.json (Claude incelemesi), tests/unit (pytest). Bu dosya build_tests_xlsx.py ile üretilir; tablolardaki değerler diğer sayfalara formülle bağlıdır.
A5: Neler, nasıl test edildi?
A6: 1. Arama testi: cevaplanabilir her sorunun kanıt alıntısı (belgede birebir geçen cümle) getirilen 30 parçada aranır → Recall@5, Recall@10, MRR. Hakemden bağımsızdır.
A7: 2. Cevap testi: altı yapılandırmanın 624 cevabı Claude (Opus) ile tek tek okundu → doğru / yanlış, kaynağa sadık, doğru ret, gereksiz ret, uydurma.
A8: 3. Kural kontrolleri: beklenen sayılar cevapta mı, sayı ve atıf denetimleriyle ret, belirsiz soruda programlara ayırma (kodla hesaplanır).
A9: 4. Birim testleri: tests/unit altında çevrimdışı pytest testleri (sahte bileşenlerle; GPU, Docker, API yok).
A10: Yapılandırmalar aynı test setini ve aynı cevap modelini (qwen3:4b) kullanır; her basamak bir öncekine göre tek bir şeyi değiştirir.
A12: Test seti – soru türlerine göre
A13: Tür | B13: Soru | C13: Kolay | D13: Orta | E13: Zor | F13: Beklenen davranış
A14: Tek belge | B14: =COUNTIF('Test Seti'!$B$2:$B$105,$A14) -> 43 | C14: =COUNTIFS('Test Seti'!$B$2:$B$105,$A14,'Test Seti'!$C$2:$C$105,"Kolay") -> 11 | D14: =COUNTIFS('Test Seti'!$B$2:$B$105,$A14,'Test Seti'!$C$2:$C$105,"Orta") -> 21 | E14: =COUNTIFS('Test Seti'!$B$2:$B$105,$A14,'Test Seti'!$C$2:$C$105,"Zor") -> 11 | F14: Doğru ve kaynaklı cevap
A15: Çok belge | B15: =COUNTIF('Test Seti'!$B$2:$B$105,$A15) -> 16 | C15: =COUNTIFS('Test Seti'!$B$2:$B$105,$A15,'Test Seti'!$C$2:$C$105,"Kolay") -> 1 | D15: =COUNTIFS('Test Seti'!$B$2:$B$105,$A15,'Test Seti'!$C$2:$C$105,"Orta") -> 8 | E15: =COUNTIFS('Test Seti'!$B$2:$B$105,$A15,'Test Seti'!$C$2:$C$105,"Zor") -> 7 | F15: Doğru ve kaynaklı cevap
A16: Sürüm | B16: =COUNTIF('Test Seti'!$B$2:$B$105,$A16) -> 10 | C16: =COUNTIFS('Test Seti'!$B$2:$B$105,$A16,'Test Seti'!$C$2:$C$105,"Kolay") -> 1 | D16: =COUNTIFS('Test Seti'!$B$2:$B$105,$A16,'Test Seti'!$C$2:$C$105,"Orta") -> 7 | E16: =COUNTIFS('Test Seti'!$B$2:$B$105,$A16,'Test Seti'!$C$2:$C$105,"Zor") -> 2 | F16: Doğru ve kaynaklı cevap
A17: Belirsiz | B17: =COUNTIF('Test Seti'!$B$2:$B$105,$A17) -> 10 | C17: =COUNTIFS('Test Seti'!$B$2:$B$105,$A17,'Test Seti'!$C$2:$C$105,"Kolay") -> 2 | D17: =COUNTIFS('Test Seti'!$B$2:$B$105,$A17,'Test Seti'!$C$2:$C$105,"Orta") -> 6 | E17: =COUNTIFS('Test Seti'!$B$2:$B$105,$A17,'Test Seti'!$C$2:$C$105,"Zor") -> 2 | F17: Doğru ve kaynaklı cevap
A18: Cevapsız | B18: =COUNTIF('Test Seti'!$B$2:$B$105,$A18) -> 15 | C18: =COUNTIFS('Test Seti'!$B$2:$B$105,$A18,'Test Seti'!$C$2:$C$105,"Kolay") -> 3 | D18: =COUNTIFS('Test Seti'!$B$2:$B$105,$A18,'Test Seti'!$C$2:$C$105,"Orta") -> 10 | E18: =COUNTIFS('Test Seti'!$B$2:$B$105,$A18,'Test Seti'!$C$2:$C$105,"Zor") -> 2 | F18: Ret (bilgi bulunamadı)
A19: Kapsam dışı | B19: =COUNTIF('Test Seti'!$B$2:$B$105,$A19) -> 10 | C19: =COUNTIFS('Test Seti'!$B$2:$B$105,$A19,'Test Seti'!$C$2:$C$105,"Kolay") -> 4 | D19: =COUNTIFS('Test Seti'!$B$2:$B$105,$A19,'Test Seti'!$C$2:$C$105,"Orta") -> 4 | E19: =COUNTIFS('Test Seti'!$B$2:$B$105,$A19,'Test Seti'!$C$2:$C$105,"Zor") -> 2 | F19: Ret (kapsam dışı)
A20: Toplam | B20: =SUM(B14:B19) -> 104 | C20: =SUM(C14:C19) -> 22 | D20: =SUM(D14:D19) -> 56 | E20: =SUM(E14:E19) -> 26 | F20: =COUNTIF('Test Seti'!$K$2:$K$105,"Doğrulandı")&" / "&B20&" insan incelemesinden geçti" -> 0 / 104 insan incelemesinden geçti
A23: Arama testi – yapılandırmaya göre (kanıt alıntısı, 77 soru)
A24: Yapılandırma (yöntem) | B24: R@5 | C24: R@10 | D24: MRR | E24: 1. sırada | F24: 2–5 | G24: 6–30 | H24: Yok (30 adayda) | I24: Ölçülen soru
A25: v0 – sabit pencere (512/64), dense arama | B25: ='Arama Sonuçları'!F108 -> 0.28354978 | C25: ='Arama Sonuçları'!G108 -> 0.35497835 | D25: ='Arama Sonuçları'!H108 -> 0.24108916 | E25: =COUNTIF('Arama Sonuçları'!$E$3:$E$106,1) -> 11 | F25: =COUNTIFS('Arama Sonuçları'!$E$3:$E$106,">=2",'Arama Sonuçları'!$E$3:$E$106,"<=5") -> 16 | G25: =COUNTIFS('Arama Sonuçları'!$E$3:$E$106,">=6",'Arama Sonuçları'!$E$3:$E$106,"<=30") -> 21 | H25: =COUNTIF('Arama Sonuçları'!$E$3:$E$106,"—") -> 29 | I25: ='Arama Sonuçları'!E109 -> 77
A26: v0r – sabit pencere (512/64), dense arama + reranker | B26: ='Arama Sonuçları'!J108 -> 0.48701299 | C26: ='Arama Sonuçları'!K108 -> 0.51298701 | D26: ='Arama Sonuçları'!L108 -> 0.40125513 | E26: =COUNTIF('Arama Sonuçları'!$I$3:$I$106,1) -> 24 | F26: =COUNTIFS('Arama Sonuçları'!$I$3:$I$106,">=2",'Arama Sonuçları'!$I$3:$I$106,"<=5") -> 19 | G26: =COUNTIFS('Arama Sonuçları'!$I$3:$I$106,">=6",'Arama Sonuçları'!$I$3:$I$106,"<=30") -> 5 | H26: =COUNTIF('Arama Sonuçları'!$I$3:$I$106,"—") -> 29 | I26: ='Arama Sonuçları'!I109 -> 77
A27: v1 – yapı bazlı parçalama + bağlam başlığı, dense arama | B27: ='Arama Sonuçları'!N108 -> 0.43939394 | C27: ='Arama Sonuçları'!O108 -> 0.55411255 | D27: ='Arama Sonuçları'!P108 -> 0.41898959 | E27: =COUNTIF('Arama Sonuçları'!$M$3:$M$106,1) -> 25 | F27: =COUNTIFS('Arama Sonuçları'!$M$3:$M$106,">=2",'Arama Sonuçları'!$M$3:$M$106,"<=5") -> 14 | G27: =COUNTIFS('Arama Sonuçları'!$M$3:$M$106,">=6",'Arama Sonuçları'!$M$3:$M$106,"<=30") -> 26 | H27: =COUNTIF('Arama Sonuçları'!$M$3:$M$106,"—") -> 12 | I27: ='Arama Sonuçları'!M109 -> 77
A28: v2 – yapı bazlı parçalama + bağlam başlığı, hibrit arama (BM25 + dense, RRF) | B28: ='Arama Sonuçları'!R108 -> 0.54329004 | C28: ='Arama Sonuçları'!S108 -> 0.61688312 | D28: ='Arama Sonuçları'!T108 -> 0.47705432 | E28: =COUNTIF('Arama Sonuçları'!$Q$3:$Q$106,1) -> 28 | F28: =COUNTIFS('Arama Sonuçları'!$Q$3:$Q$106,">=2",'Arama Sonuçları'!$Q$3:$Q$106,"<=5") -> 21 | G28: =COUNTIFS('Arama Sonuçları'!$Q$3:$Q$106,">=6",'Arama Sonuçları'!$Q$3:$Q$106,"<=30") -> 16 | H28: =COUNTIF('Arama Sonuçları'!$Q$3:$Q$106,"—") -> 12 | I28: ='Arama Sonuçları'!Q109 -> 77
A29: v3 – yapı bazlı parçalama + bağlam başlığı, hibrit arama (BM25 + dense, RRF) + reranker | B29: ='Arama Sonuçları'!V108 -> 0.6991342 | C29: ='Arama Sonuçları'!W108 -> 0.75108225 | D29: ='Arama Sonuçları'!X108 -> 0.61247212 | E29: =COUNTIF('Arama Sonuçları'!$U$3:$U$106,1) -> 38 | F29: =COUNTIFS('Arama Sonuçları'!$U$3:$U$106,">=2",'Arama Sonuçları'!$U$3:$U$106,"<=5") -> 22 | G29: =COUNTIFS('Arama Sonuçları'!$U$3:$U$106,">=6",'Arama Sonuçları'!$U$3:$U$106,"<=30") -> 5 | H29: =COUNTIF('Arama Sonuçları'!$U$3:$U$106,"—") -> 12 | I29: ='Arama Sonuçları'!U109 -> 77
A30: v3b – v3 ile aynı, embedding modeli bge-m3 | B30: ='Arama Sonuçları'!Z108 -> 0.72727273 | C30: ='Arama Sonuçları'!AA108 -> 0.78354978 | D30: ='Arama Sonuçları'!AB108 -> 0.62273276 | E30: =COUNTIF('Arama Sonuçları'!$Y$3:$Y$106,1) -> 38 | F30: =COUNTIFS('Arama Sonuçları'!$Y$3:$Y$106,">=2",'Arama Sonuçları'!$Y$3:$Y$106,"<=5") -> 24 | G30: =COUNTIFS('Arama Sonuçları'!$Y$3:$Y$106,">=6",'Arama Sonuçları'!$Y$3:$Y$106,"<=30") -> 7 | H30: =COUNTIF('Arama Sonuçları'!$Y$3:$Y$106,"—") -> 8 | I30: ='Arama Sonuçları'!Y109 -> 77
A32: Recall@5 – soru türüne göre
A33: Tür | B33: v0 | C33: v0r | D33: v1 | E33: v2 | F33: v3 | G33: v3b
A34: Tek belge | B34: =IFERROR(AVERAGEIFS('Arama Sonuçları'!$F$3:$F$106,'Arama Sonuçları'!$B$3:$B$106,$A34),0) -> 0.35714286 | C34: =IFERROR(AVERAGEIFS('Arama Sonuçları'!$J$3:$J$106,'Arama Sonuçları'!$B$3:$B$106,$A34),0) -> 0.5952381 | D34: =IFERROR(AVERAGEIFS('Arama Sonuçları'!$N$3:$N$106,'Arama Sonuçları'!$B$3:$B$106,$A34),0) -> 0.5952381 | E34: =IFERROR(AVERAGEIFS('Arama Sonuçları'!$R$3:$R$106,'Arama Sonuçları'!$B$3:$B$106,$A34),0) -> 0.67857143 | F34: =IFERROR(AVERAGEIFS('Arama Sonuçları'!$V$3:$V$106,'Arama Sonuçları'!$B$3:$B$106,$A34),0) -> 0.83333333 | G34: =IFERROR(AVERAGEIFS('Arama Sonuçları'!$Z$3:$Z$106,'Arama Sonuçları'!$B$3:$B$106,$A34),0) -> 0.88095238
A35: Çok belge | B35: =IFERROR(AVERAGEIFS('Arama Sonuçları'!$F$3:$F$106,'Arama Sonuçları'!$B$3:$B$106,$A35),0) -> 0.23958333 | C35: =IFERROR(AVERAGEIFS('Arama Sonuçları'!$J$3:$J$106,'Arama Sonuçları'!$B$3:$B$106,$A35),0) -> 0.46875 | D35: =IFERROR(AVERAGEIFS('Arama Sonuçları'!$N$3:$N$106,'Arama Sonuçları'!$B$3:$B$106,$A35),0) -> 0.23958333 | E35: =IFERROR(AVERAGEIFS('Arama Sonuçları'!$R$3:$R$106,'Arama Sonuçları'!$B$3:$B$106,$A35),0) -> 0.45833333 | F35: =IFERROR(AVERAGEIFS('Arama Sonuçları'!$V$3:$V$106,'Arama Sonuçları'!$B$3:$B$106,$A35),0) -> 0.625 | G35: =IFERROR(AVERAGEIFS('Arama Sonuçları'!$Z$3:$Z$106,'Arama Sonuçları'!$B$3:$B$106,$A35),0) -> 0.625
A36: Sürüm | B36: =IFERROR(AVERAGEIFS('Arama Sonuçları'!$F$3:$F$106,'Arama Sonuçları'!$B$3:$B$106,$A36),0) -> 0.2 | C36: =IFERROR(AVERAGEIFS('Arama Sonuçları'!$J$3:$J$106,'Arama Sonuçları'!$B$3:$B$106,$A36),0) -> 0.4 | D36: =IFERROR(AVERAGEIFS('Arama Sonuçları'!$N$3:$N$106,'Arama Sonuçları'!$B$3:$B$106,$A36),0) -> 0.5 | E36: =IFERROR(AVERAGEIFS('Arama Sonuçları'!$R$3:$R$106,'Arama Sonuçları'!$B$3:$B$106,$A36),0) -> 0.6 | F36: =IFERROR(AVERAGEIFS('Arama Sonuçları'!$V$3:$V$106,'Arama Sonuçları'!$B$3:$B$106,$A36),0) -> 0.8 | G36: =IFERROR(AVERAGEIFS('Arama Sonuçları'!$Z$3:$Z$106,'Arama Sonuçları'!$B$3:$B$106,$A36),0) -> 0.8
A37: Belirsiz | B37: =IFERROR(AVERAGEIFS('Arama Sonuçları'!$F$3:$F$106,'Arama Sonuçları'!$B$3:$B$106,$A37),0) -> 0.11111111 | C37: =IFERROR(AVERAGEIFS('Arama Sonuçları'!$J$3:$J$106,'Arama Sonuçları'!$B$3:$B$106,$A37),0) -> 0.11111111 | D37: =IFERROR(AVERAGEIFS('Arama Sonuçları'!$N$3:$N$106,'Arama Sonuçları'!$B$3:$B$106,$A37),0) -> 0 | E37: =IFERROR(AVERAGEIFS('Arama Sonuçları'!$R$3:$R$106,'Arama Sonuçları'!$B$3:$B$106,$A37),0) -> 0 | F37: =IFERROR(AVERAGEIFS('Arama Sonuçları'!$V$3:$V$106,'Arama Sonuçları'!$B$3:$B$106,$A37),0) -> 0.092592593 | G37: =IFERROR(AVERAGEIFS('Arama Sonuçları'!$Z$3:$Z$106,'Arama Sonuçları'!$B$3:$B$106,$A37),0) -> 0.11111111
A39: Cevap testi – Claude (Opus) incelemesi
A40: Yapılandırma (yöntem) | B40: Doğru cevap | C40: Doğruluk (/79) | D40: Sadakat | E40: Doğru ret (/25) | F40: Gereksiz ret | G40: Yanlış ret oranı | H40: Uydurma | I40: Gecikme p50 (ms)
A41: v0 – sabit pencere (512/64), dense arama | B41: =COUNTIF('Cevap Sonuçları'!$F$3:$F$106,"Doğru cevap") -> 30 | C41: =B41/COUNTIF('Cevap Sonuçları'!$D$3:$D$106,"Cevap") -> 0.37974684 | D41: =COUNTIF('Cevap Sonuçları'!$G$3:$G$106,"Evet")/(COUNTIF('Cevap Sonuçları'!$G$3:$G$106,"Evet")+COUNTIF('Cevap Sonuçları'!$G$3:$G$106,"Hayır")) -> 0.53225806 | E41: =COUNTIF('Cevap Sonuçları'!$F$3:$F$106,"Doğru ret")/COUNTIF('Cevap Sonuçları'!$D$3:$D$106,"Ret*") -> 0.76 | F41: =COUNTIF('Cevap Sonuçları'!$F$3:$F$106,"Gereksiz ret*") -> 6 | G41: =F41/COUNTIF('Cevap Sonuçları'!$D$3:$D$106,"Cevap") -> 0.075949367 | H41: =COUNTIF('Cevap Sonuçları'!$F$3:$F$106,"Uydurma") -> 6 | I41: 1370
A42: v0r – sabit pencere (512/64), dense arama + reranker | B42: =COUNTIF('Cevap Sonuçları'!$J$3:$J$106,"Doğru cevap") -> 44 | C42: =B42/COUNTIF('Cevap Sonuçları'!$D$3:$D$106,"Cevap") -> 0.55696203 | D42: =COUNTIF('Cevap Sonuçları'!$K$3:$K$106,"Evet")/(COUNTIF('Cevap Sonuçları'!$K$3:$K$106,"Evet")+COUNTIF('Cevap Sonuçları'!$K$3:$K$106,"Hayır")) -> 0.55357143 | E42: =COUNTIF('Cevap Sonuçları'!$J$3:$J$106,"Doğru ret")/COUNTIF('Cevap Sonuçları'!$D$3:$D$106,"Ret*") -> 0.68 | F42: =COUNTIF('Cevap Sonuçları'!$J$3:$J$106,"Gereksiz ret*") -> 4 | G42: =F42/COUNTIF('Cevap Sonuçları'!$D$3:$D$106,"Cevap") -> 0.050632911 | H42: =COUNTIF('Cevap Sonuçları'!$J$3:$J$106,"Uydurma") -> 8 | I42: 2076
A43: v1 – yapı bazlı parçalama + bağlam başlığı, dense arama | B43: =COUNTIF('Cevap Sonuçları'!$N$3:$N$106,"Doğru cevap") -> 33 | C43: =B43/COUNTIF('Cevap Sonuçları'!$D$3:$D$106,"Cevap") -> 0.41772152 | D43: =COUNTIF('Cevap Sonuçları'!$O$3:$O$106,"Evet")/(COUNTIF('Cevap Sonuçları'!$O$3:$O$106,"Evet")+COUNTIF('Cevap Sonuçları'!$O$3:$O$106,"Hayır")) -> 0.57377049 | E43: =COUNTIF('Cevap Sonuçları'!$N$3:$N$106,"Doğru ret")/COUNTIF('Cevap Sonuçları'!$D$3:$D$106,"Ret*") -> 0.84 | F43: =COUNTIF('Cevap Sonuçları'!$N$3:$N$106,"Gereksiz ret*") -> 9 | G43: =F43/COUNTIF('Cevap Sonuçları'!$D$3:$D$106,"Cevap") -> 0.11392405 | H43: =COUNTIF('Cevap Sonuçları'!$N$3:$N$106,"Uydurma") -> 4 | I43: 1105
A44: v2 – yapı bazlı parçalama + bağlam başlığı, hibrit arama (BM25 + dense, RRF) | B44: =COUNTIF('Cevap Sonuçları'!$R$3:$R$106,"Doğru cevap") -> 41 | C44: =B44/COUNTIF('Cevap Sonuçları'!$D$3:$D$106,"Cevap") -> 0.51898734 | D44: =COUNTIF('Cevap Sonuçları'!$S$3:$S$106,"Evet")/(COUNTIF('Cevap Sonuçları'!$S$3:$S$106,"Evet")+COUNTIF('Cevap Sonuçları'!$S$3:$S$106,"Hayır")) -> 0.69565217 | E44: =COUNTIF('Cevap Sonuçları'!$R$3:$R$106,"Doğru ret")/COUNTIF('Cevap Sonuçları'!$D$3:$D$106,"Ret*") -> 0.76 | F44: =COUNTIF('Cevap Sonuçları'!$R$3:$R$106,"Gereksiz ret*") -> 6 | G44: =F44/COUNTIF('Cevap Sonuçları'!$D$3:$D$106,"Cevap") -> 0.075949367 | H44: =COUNTIF('Cevap Sonuçları'!$R$3:$R$106,"Uydurma") -> 6 | I44: 1126
A45: v3 – yapı bazlı parçalama + bağlam başlığı, hibrit arama (BM25 + dense, RRF) + reranker | B45: =COUNTIF('Cevap Sonuçları'!$V$3:$V$106,"Doğru cevap") -> 50 | C45: =B45/COUNTIF('Cevap Sonuçları'!$D$3:$D$106,"Cevap") -> 0.63291139 | D45: =COUNTIF('Cevap Sonuçları'!$W$3:$W$106,"Evet")/(COUNTIF('Cevap Sonuçları'!$W$3:$W$106,"Evet")+COUNTIF('Cevap Sonuçları'!$W$3:$W$106,"Hayır")) -> 0.80555556 | E45: =COUNTIF('Cevap Sonuçları'!$V$3:$V$106,"Doğru ret")/COUNTIF('Cevap Sonuçları'!$D$3:$D$106,"Ret*") -> 0.8 | F45: =COUNTIF('Cevap Sonuçları'!$V$3:$V$106,"Gereksiz ret*") -> 5 | G45: =F45/COUNTIF('Cevap Sonuçları'!$D$3:$D$106,"Cevap") -> 0.063291139 | H45: =COUNTIF('Cevap Sonuçları'!$V$3:$V$106,"Uydurma") -> 5 | I45: 1771
A46: v3b – v3 ile aynı, embedding modeli bge-m3 | B46: =COUNTIF('Cevap Sonuçları'!$Z$3:$Z$106,"Doğru cevap") -> 49 | C46: =B46/COUNTIF('Cevap Sonuçları'!$D$3:$D$106,"Cevap") -> 0.62025316 | D46: =COUNTIF('Cevap Sonuçları'!$AA$3:$AA$106,"Evet")/(COUNTIF('Cevap Sonuçları'!$AA$3:$AA$106,"Evet")+COUNTIF('Cevap Sonuçları'!$AA$3:$AA$106,"Hayır")) -> 0.76056338 | E46: =COUNTIF('Cevap Sonuçları'!$Z$3:$Z$106,"Doğru ret")/COUNTIF('Cevap Sonuçları'!$D$3:$D$106,"Ret*") -> 0.88 | F46: =COUNTIF('Cevap Sonuçları'!$Z$3:$Z$106,"Gereksiz ret*") -> 6 | G46: =F46/COUNTIF('Cevap Sonuçları'!$D$3:$D$106,"Cevap") -> 0.075949367 | H46: =COUNTIF('Cevap Sonuçları'!$Z$3:$Z$106,"Uydurma") -> 3 | I46: 2923
...

Sheet Test Seti
A1: ID | B1: Tür | C1: Zorluk | D1: Soru | E1: Beklenen cevap | F1: Kanıt alıntıları | G1: Beklenen belgeler | H1: Beklenen sayılar | I1: Program kodu | J1: Cevaplanmalı mı | K1: İnsan incelemesi | L1: Yazar notu
A2: q001 | B2: Tek belge | C2: Kolay | D2: KOBİ olarak 1507 programından proje desteği alırsam TÜBİTAK harcamalarımın en fazla yüzde kaçını karşılar? | E2: 1507 programında destek oranı her dönem için en fazla %75'tir. | F2: [mevzuat-031] Bu programda uygulanacak destek oranı her dönem için en fazla %75 olarak belirlenmiştir. | G2: mevzuat-031 | H2: 75 | I2: 1507 | J2: Evet | K2: Doğrulanmadı
A3: q002 | B3: Çok belge | C3: Kolay | D3: Büyük ölçekli bir firmayız; 1501 programından hangi destek oranıyla yararlanabiliriz? | E3: 1501 Uygulama Esaslarına göre destek oranı büyük kuruluşlar için en fazla %60, KOBİ'ler için en fazla %75'tir. Ancak güncel 2026-2 çağrısına göre 1501'e yalnız KOBİ niteliğindeki sermaye şirketleri başvurabilir; büyük ölçekli firma bu çağrıya başvuramaz. | F3: [mevzuat-030] Destek oranı büyük kuruluşlar için en fazla % 60 ve KOBİ ölçeğindeki kuruluşlar içinse en fazla %75 olarak uygulanır. [dosya-10f733d7f6a2] 1501 ve 1507 destek programlarına sadece KOBİ niteliğinde olan sermaye şirketleri başvuru yapabilmektedir. | G3: mevzuat-030 dosya-10f733d7f6a2 | H3: 60, 75 | I3: 1501 | J3: Evet | K3: Doğrulanmadı
A4: q003 | B4: Tek belge | C4: Zor | D4: 1501 projesinde doktoralı bir personelin aylık maliyeti beyan edilirken brüt asgari ücretin kaç katıyla sınırlandırılır? Lisans mezunu için durum nedir? | E4: Ortalama aylık maliyet doktoralılar için brüt asgari ücretin 12 katı, lisans/yüksek lisans mezunları için 8 katı ile sınırlandırılır. | F4: [mevzuat-030] Eğitim Durumu Asgari Ücret Katı Doktora 12 katı Lisans/Yüksek Lisans 8 katı | G4: mevzuat-030 | H4: 12, 8 | I4: 1501 | J4: Evet | K4: Doğrulanmadı
A5: q004 | B5: Tek belge | C5: Zor | D5: 1501 projesi için aldığımız kalıp seri üretimde de kullanılacak. Bu kalıbın maliyeti desteğe nasıl dahil edilir? | E5: Seri üretimde de kullanılacak alet, teçhizat ve kalıp gibi alımlar proje süresiyle orantılı olarak aylık %2 oranıyla destek kapsamına alınır (maliyet x proje süresi (ay) x %2). | F5: [mevzuat-030] ilgili giderler proje süresiyle orantılı olarak aylık % 2 oranı ile destek kapsamına alınır | G5: mevzuat-030 | H5: 2 | I5: 1501 | J5: Evet | K5: Doğrulanmadı
A6: q005 | B6: Tek belge | C6: Orta | D6: 1501'de dönem raporunu (AGY300) son tarihten sonra gönderirsem ne olur, kesinti var mı? | E6: Son gönderim tarihini izleyen 30 gün içinde sunulursa geciken her gün için %1, en fazla %30 kesinti yapılarak değerlendirme tamamlanır; 30 günü aşan gecikmede %30 kesinti uygulanır. | F6: [mevzuat-030] geciken her gün için %1 ve en fazla %30 oranında kesinti yapılarak dönem değerlendirmesi tamamlanır | G6: mevzuat-030 | H6: 30, 1 | I6: 1501 | J6: Evet | K6: Doğrulanmadı
A7: q006 | B7: Tek belge | C7: Orta | D7: 1507 KOBİ Ar-Ge Başlangıç programında bir firmanın kaç projesi desteklenebiliyor? | E7: KOBİ ölçeğindeki işletmelerin, en az ikisi ortaklı başvuru olmak kaydıyla ilk beş projesi desteklenir. | F7: [mevzuat-031] KOBİ ölçeğindeki işletmelerin en az ikisi ortaklı başvuru olmak kaydıyla ilk beş projesi desteklenir | G7: mevzuat-031 | H7: beş | I7: 1507 | J7: Evet | K7: Doğrulanmadı
A8: q007 | B8: Tek belge | C8: Zor | D8: 1509 uluslararası projemizde yurt dışından danışmanlık ve hizmet almayı planlıyoruz. Bunun bir sınırı var mı? | E8: Toplam yurt dışı danışmanlık ve hizmet alımlarının dönemsel desteklemeye esas harcama tutarları toplamı içindeki payı %20 ile sınırlıdır; ana Ar-Ge faaliyetlerinin Türkiye'de yapılması gerekir. | F8: [mevzuat-032] projenin dönemsel desteklemeye esas harcama tutarları toplamı içindeki payı %20 ile sınırlandırılır | G8: mevzuat-032 | H8: 20 | I8: 1509 | J8: Evet | K8: Doğrulanmadı
A9: q009 | B9: Tek belge | C9: Orta | D9: 1511 projesinde aynı personel için bir ay içinde TÜBİTAK'a kaç günlük maliyet beyan edebilirim? | E9: Her ay için en fazla 30 günlük maliyet beyan edilebilir. | F9: [mevzuat-079] Desteklenen proje kapsamında her ay için TÜBİTAK’a en fazla 30 günlük maliyet beyan edilebilir. | G9: mevzuat-079 | H9: 30 | I9: 1511 | J9: Evet | K9: Doğrulanmadı
A10: q010 | B10: Tek belge | C10: Orta | D10: 1512 Girişimcilik Destek Programında Aşama 2 iş planı faaliyetleri en fazla ne kadar sürebilir? | E10: Aşama 2 kapsamında destek süresi ek süreler dahil en fazla 18 aydır. | F10: [mevzuat-101] destek süresi ek süreler de dâhil olmak üzere en fazla onsekiz (18) aydır | G10: mevzuat-101 | H10: 18 | I10: 1512 | J10: Evet | K10: Doğrulanmadı
A11: q011 | B11: Tek belge | C11: Zor | D11: BiGG Yatırım 2026-2 çağrısında TÜBİTAK BİGG Fonu girişim şirketine ne kadar yatırım yapıyor ve karşılığında kaç hisse alıyor? | E11: Yatırım ve Pay Sahipleri Sözleşmesi kapsamında kuruluşun %3 payı karşılığında 1.350.000 TL yatırım yapılır. | F11: [dosya-4a616f06b928] kuruluşun %3 payı karşılığında TÜBİTAK BİGG Fonu kuruluşa 1.350.000 TL yatırım yapacaktır | G11: dosya-4a616f06b928 | H11: 3, 1.350.000 | I11: 1812 | J11: Evet | K11: Doğrulanmadı
A12: q012 | B12: Tek belge | C12: Orta | D12: BiGG Yatırım hızlandırma programına kabul edilmek için iş fikrimin değerlendirmede kaç puan alması gerekiyor? | E12: Uygulayıcı kuruluşun puanlamasında (10 üzerinden) değerlendirilen boyutların her birinden en az 7 puan alınmalıdır. | F12: [dosya-4a616f06b928] her bir boyut için 10 üzerinden yapılacak puanlama sonucunda; ilgili boyutların her birinden en az 7 puan almalıdır | G12: dosya-4a616f06b928 | H12: 7 | I12: 1812 | J12: Evet | K12: Doğrulanmadı
A13: q014 | B13: Tek belge | C13: Kolay | D13: Sipariş Ar-Ge (1707) 2026-3 çağrısında proje süresi uzatılırsa 24 ayı geçebilir mi? | E13: Hayır. Proje süresi en fazla 24 aydır ve destek süresi uzatılsa dahi 24 ay aşılmaz. | F13: [dosya-b5665606654f] Proje süresi en fazla 24 aydır. Destek süresi uzatılsa dahi yirmi dört ay aşılmaz. | G13: dosya-b5665606654f | H13: 24 | I13: 1707 | J13: Evet | K13: Doğrulanmadı
... A25: q027 | B25: Tek belge | C25: Orta | D25: 2213 Yurt Dışı Lisansüstü Burs Programında yurt dışında toplam ne kadar süre burs alınabilir? | E25: Yurt dışında öğrenime başlama tarihinden itibaren toplamda 24 aya kadar burs ve destek ödenebilir; geriye dönük ödeme yapılmaz. | F25: [mevzuat-040] toplamda 24 aya kadar burs ve destek ödenebilir | G25: mevzuat-040 | H25: 24 | I25: 2213 | J25: Evet | K25: Doğrulanmadı
A26: q028 | B26: Tek belge | C26: Kolay | D26: 2224-A desteğinden aynı yıl içinde ikinci kez yararlanabilir miyim? | E26: Hayır; başvuru koşullarından biri 2224-A programından ilgili yıl içinde yararlanılmamış olmasıdır. | F26: [dosya-b82f05be2ea3] 2224-A programından ilgili yıl içinde yararlanılmamış olması | G26: dosya-b82f05be2ea3 | I26: 2224 | J26: Evet | K26: Doğrulanmadı
A27: q029 | B27: Tek belge | C27: Orta | D27: 2224-A ile konferansa katıldıktan sonra izleme belgelerini ne kadar süre içinde sisteme yüklemem gerekiyor? | E27: Etkinliğin bitiş tarihinden ya da destek sonuç tarihinden sonraki otuz gün içinde BİDEB sistemine yüklenmelidir. | F27: [dosya-b82f05be2ea3] etkinliğin bitiş tarihinden ya da destek sonuç tarihinden sonraki otuz gün içinde | G27: dosya-b82f05be2ea3 | H27: otuz | I27: 2224 | J27: Evet | K27: Doğrulanmadı
A28: q031 | B28: Tek belge | C28: Orta | D28: 4007 kapsamında büyük ölçekli bilim festivali düzenlersek ne kadar destek alabiliriz? | E28: Bilim Festivalleri için destek üst limiti (PTİ hariç) 1.500.000 TL'dir (KDV dahil); bilim şenlikleri için 450.000 TL'dir. | F28: [dosya-4806f8f8bca1] Bilim Festivalleri (Büyük Ölçekli Bilim Şenlikleri) için 1.500.000 TL (KDV dâhil)’dir | G28: dosya-4806f8f8bca1 | H28: 1.500.000 | I28: 4007 | J28: Evet | K28: Doğrulanmadı
A29: q032 | B29: Tek belge | C29: Zor | D29: 4006-A bilim fuarında 20 alt proje sergilenecekse okulumuza toplam ne kadar destek ödenir? | E29: Destek = hazırlık desteği 7.000 TL + alt proje başına 750 TL; 20 alt proje için toplam 22.000 TL (KDV dahil) ödenir. | F29: [dosya-0f15ecfa44a1] Bilim Fuarı Hazırlık Desteği (7.000 TL) + (Sergilenecek Alt Proje Sayısı x 750 TL) [dosya-0f15ecfa44a1] 20 alt projesi kabul edilen bir proje yürütücüsüne toplam 22.000 TL (KDV dâhil) proje destek miktarı ödenir | G29: dosya-0f15ecfa44a1 | H29: 22.000 | I29: 4006 | J29: Evet | K29: Doğrulanmadı
A30: q033 | B30: Tek belge | C30: Orta | D30: 4008 projesinde her bir etkinlik dönemi en az kaç gün olmalı? | E30: Her bir etkinlik dönemi en az 4 gün olacak şekilde planlanmalıdır. | F30: [dosya-fc6dead14833] Her bir etkinlik dönemi en az 4 gün olacak şekilde planlanmalıdır. | G30: dosya-fc6dead14833 | H30: 4 | I30: 4008 | J30: Evet | K30: Doğrulanmadı
A31: q035 | B31: Tek belge | C31: Orta | D31: Kurum hissesinden bursiyer ödemesi veya PTİ ödemesi yapabilir miyiz? | E31: Hayır. Kurum hissesinden burs ve PTİ ödemesi yapılamaz. | F31: [mevzuat-048] Kurum hissesinden burs ve PTİ ödemesi yapılamaz. | G31: mevzuat-048 | J31: Evet | K31: Doğrulanmadı
A32: q036 | B32: Tek belge | C32: Kolay | D32: TÜBİTAK başvurumun reddine itiraz etmek için kaç günüm var? | E32: İtiraz başvuru süresi, işlemin tebliğinden itibaren 15 gündür; son gün tatile denk gelirse izleyen ilk iş gününün bitimine kadar uzar. Başvuru TÜBİMER Online Sistemi'nden yapılır. | F32: [mevzuat-116] itiraza konu işlemin ilgiliye tebliğinden (yazılı veya elektronik olarak gerçekleştirilen bildirimden) itibaren 15 gündür | G32: mevzuat-116 | H32: 15 | J32: Evet | K32: Doğrulanmadı
A33: q037 | B33: Tek belge | C33: Orta | D33: ARDEB panel değerlendirmesinde bir panelde kaç panelist bulunur ve en fazla kaç öneri görüşülür? | E33: Her panel en çok on proje önerisini değerlendirmek üzere en az beş, en çok dokuz panelistten oluşturulur. | F33: [mevzuat-044] Her panel, en çok on proje önerisinin bilimsel değerlendirmesini yapmak üzere, en az beş en çok dokuz panelistten oluşturulur. | G33: mevzuat-044 | H33: beş, dokuz, on | J33: Evet | K33: Doğrulanmadı
A34: q038 | B34: Tek belge | C34: Zor | D34: Teknoparkta yönetici şirketin kurucuları arasında kimlerin bulunması zorunludur? | E34: Yönetici şirketin kurucuları arasında Bölgenin içinde veya bulunduğu ilde yer alan en az bir üniversite veya yüksek teknoloji enstitüsü ya da kamu AR-GE merkez veya enstitüsü bulunur. | F34: [kanun-4691] yönetici şirketin kurucuları arasında, Bölgenin içinde veya bulunduğu ilde yer alan en az bir üniversite veya yüksek teknoloji enstitüsü ya da kamu AR-GE merkez veya enstitüsü bulunur | G34: kanun-4691 | J34: Evet | K34: Doğrulanmadı
A35: q039 | B35: Tek belge | C35: Zor | D35: 5746 sayılı Kanuna göre doktoralı Ar-Ge personelinin gelir vergisi stopajının yüzde kaçı terkin edilir? | E35: Doktoralılar (ve desteklenecek alanlarda en az yüksek lisanslılar) için %95; yüksek lisanslılar için %90; diğerleri için %80 terkin edilir. | F35: [kanun-5746] doktoralı olanlar ile desteklenecek program alanlarından birinde en az yüksek lisans derecesine sahip olanlar için yüzde doksan beşi | G35: kanun-5746 | H35: 95, 90, 80 | J35: Evet | K35: Doğrulanmadı
A36: q040 | B36: Tek belge | C36: Kolay | D36: Şahıs şirketim var; 1505 projesinde müşteri kuruluş olabilir miyim? | E36: Hayır. 1505'te müşteri kuruluşun sermaye şirketi olması gerekir; şahıs işletmeleri müşteri kuruluş olamaz. | F36: [dosya-358f2addd2d5] Şahıs işletmeleri müşteri kuruluş olabilir mi? Hayır. Müşteri kuruluş sermaye şirketi olmalıdır. | G36: dosya-358f2addd2d5 | I36: 1505 | J36: Evet | K36: Doğrulanmadı
A37: q042 | B37: Tek belge | C37: Zor | D37: TEYDEB destek limitleri tablosuna göre 1515 Öncül Ar-Ge Laboratuvarları programında proje bütçesi üst limiti nedir? | E37: Üst limit tablosunda 1515 için proje bütçesi üst limiti yıllık 25.000.000 TL'dir. | F37: [dosya-6a5eda267423] 1515: 25.000.000 TL (Yıllık) | G37: dosya-6a5eda267423 | H37: 25.000.000 | I37: 1515 | J37: Evet | K37: Doğrulanmadı | L37: Kaynak 2024-03 tarihli üst limit tablosu (XLSX); daha güncel bir değer yayımlanmış olabilir.
A38: q043 | B38: Tek belge | C38: Zor | D38: 1513 Teknoloji Transfer Ofisleri programında Kapasite Geliştirme Aşamasında destek oranı yüzde kaç? | E38: Kapasite Geliştirme Aşamasında destek oranı %80'dir; Hedef Odaklı Gelişim Aşamasında oran %40+%[(performans puanı-1)x10] formülüyle hesaplanır. | F38: [dosya-6a5eda267423] Program kapsamında desteklenen projelerin Kapasite Geliştirme Aşaması’nda destek oranı %80’dir. | G38: dosya-6a5eda267423 | H38: 80 | I38: 1513 | J38: Evet | K38: Doğrulanmadı | L38: Kaynak 2024-03 tarihli üst limit tablosu; 1513 uygulama esaslarıyla (mevzuat-103) çapraz kontrol edilebilir.
A39: q044 | B39: Çok belge | C39: Orta | D39: 1501 Uygulama Esaslarında proje süresi üst sınırı nedir ve 2026 yılı 2. çağrısına kaç aylık proje ile başvurulabilir? | E39: Esaslara göre destek süresi en fazla 36 aydır; 2026-2 çağrısına ise en fazla 24 ay süreli proje ile başvurulabilir (gerekirse izleme sırasında 36 ayı geçmemek üzere en fazla %50 uzatılabilir). | F39: [mevzuat-030] Destek süresi proje bazında en fazla otuz altı aydır. [dosya-10f733d7f6a2] Çağrıya en fazla 24 ay süreli proje başvurusu yapılabilir. | G39: mevzuat-030 dosya-10f733d7f6a2 | H39: 36, 24 | I39: 1501 | J39: Evet | K39: Doğrulanmadı
A40: q045 | B40: Çok belge | C40: Orta | D40: 1501 ve 1507 programları arasında azami proje süresi açısından fark nedir? | E40: 1501'de destek süresi en fazla 36 ay, 1507'de en fazla 18 aydır; yani 1501 projeleri 18 ay daha uzun olabilir. | F40: [mevzuat-030] Destek süresi proje bazında en fazla otuz altı aydır. [mevzuat-031] Destek süresi proje bazında en fazla on sekiz (18) aydır. | G40: mevzuat-030 mevzuat-031 | H40: 36, 18 | I40: 1501, 1507 | J40: Evet | K40: Doğrulanmadı
A41: q046 | B41: Çok belge | C41: Zor | D41: 1501 projesinde çalışan Ar-Ge personelim 5746 sayılı Kanundaki gelir vergisi stopajı teşvikinden yararlanıyor. Bu teşvik tutarını TÜBİTAK'a personel maliyeti olarak beyan edebilir miyim? | E41: Hayır. 5746 kapsamında TÜBİTAK tarafından yürütülen projelerde çalışan Ar-Ge personeli stopaj teşvikinden yararlanabilir; ancak 1501 Esaslarına göre bu teşvik, istisna ve destekler proje personel maliyetine dahil edilmez, TÜBİTAK'a beyan edilmez ve desteklenmez. | F41: [kanun-5746] ya da TÜBİTAK tarafından yürütülen Ar-Ge ve yenilik projelerinde [mevzuat-030] proje personel maliyetine dahil edilmez, TÜBİTAK’a beyan edilmez ve desteklenmez | G41: kanun-5746 mevzuat-030 | I41: 1501 | J41: Evet | K41: Doğrulanmadı
A42: q047 | B42: Çok belge | C42: Orta | D42: Teknoparktaki yazılım kazançlarına tanınan vergi istisnası ile 5746 sayılı Kanun kapsamındaki destekler hangi tarihe kadar geçerli? | E42: Her ikisi de 31/12/2028'e kadar geçerlidir: 4691 sayılı Kanun'daki kazanç istisnası 31/12/2028'e kadar, 5746 sayılı Kanun da 31/12/2028'e kadar uygulanır. | F42: [kanun-4691] elde ettikleri kazançları 31/12/2028 tarihine kadar gelir ve kurumlar vergisinden müstesnadır [kanun-5746] Bu Kanun 31/12/2028 tarihine kadar uygulanmak üzere | G42: kanun-4691 kanun-5746 | H42: 31/12/2028 | J42: Evet | K42: Doğrulanmadı
A43: q048 | B43: Çok belge | C43: Zor | D43: 1501 projemizde destek kapsamına itiraz etmek istiyoruz; ayrıca başka bir başvurumuz reddedildi. Bu iki itiraz için süreler nedir? | E43: 1501 Esaslarına göre destek kapsamına itiraz, destek karar yazısı tarihinden itibaren en fazla 2 ay içinde yapılır. Başvuru değerlendirme sonucuna (ret) itiraz ise İtiraz Yönetmeliğine göre tebliğden itibaren 15 gün içinde TÜBİMER'den yapılır. | F43: [mevzuat-030] Destek kapsamına itirazlar, proje destek karar yazısı tarihinden itibaren en fazla iki (2) ay içinde yapılabilir. [mevzuat-116] itiraza konu işlemin ilgiliye tebliğinden (yazılı veya elektronik olarak gerçekleştirilen bildirimden) itibaren 15 gündür | G43: mevzuat-030 mevzuat-116 | H43: 2, 15 | I43: 1501 | J43: Evet | K43: Doğrulanmadı
A44: q049 | B44: Çok belge | C44: Orta | D44: 1507 Uygulama Esaslarında azami proje bütçesi rakam olarak yazıyor mu? Güncel bütçe sınırı nedir? | E44: Esaslar azami bütçeyi rakam vermeden Yönetim Kurulunun belirleyeceğini söyler; program sayfasına göre proje bütçesi en fazla 3.500.000 TL'dir. | F44: [mevzuat-031] Bu programa başvuran projelerin azami bütçesi Yönetim Kurulu tarafından belirlenir. [sayfa-sanayi__ulusal-destek-programlari__1507-tubitak-kobi-ar-ge-baslangic-destek-programi] Proje bütçesi en fazla 3.500.000 TL’dir. | G44: mevzuat-031 sayfa-sanayi__ulusal-destek-programlari__1507-tubitak-kobi-ar-ge-baslangic-destek-programi | H44: 3.500.000 | I44: 1507 | J44: Evet | K44: Doğrulanmadı
A45: q050 | B45: Çok belge | C45: Orta | D45: Büyük ölçekli bir şirket 1505 projesinde müşteri kuruluş olabilir mi; olursa bütçenin ne kadarını TÜBİTAK karşılar? | E45: Evet, şirket ölçeğine kısıtlama yoktur (SSS). Müşteri büyük ölçekli ise bütçenin %60'ını TÜBİTAK, %40'ını müşteri kuruluş karşılar (Uygulama Esasları). | F45: [dosya-358f2addd2d5] Büyük ölçekli şirketler müşteri kuruluş olabilir mi? Evet. [mevzuat-070] destek kapsamına alınan proje bütçesinin %60'ı TÜBİTAK, kalan %40'ı müşteri kuruluş tarafından karşılanır | G45: dosya-358f2addd2d5 mevzuat-070 | H45: 60, 40 | I45: 1505 | J45: Evet | K45: Doğrulanmadı
A46: q051 | B46: Çok belge | C46: Orta | D46: 1001 projesinde bütçe üst limiti nedir ve buna ek olarak kurum hissesi ne kadar verilir? | E46: 1001'de 2026 1. dönem itibarıyla destek üst limiti (burs dahil, PTİ ve kurum hissesi hariç) 3.000.000 TL'dir; kurum hissesi ayrıca proje bütçesinin %10'una kadar hesaplanarak eklenir. | F46: [sayfa-akademik__ulusal-destek-programlari__1001-bilimsel-ve-teknolojik-arastirma-projelerini-destekleme-programi] yıllık bütçe sınırlaması olmaksızın 3.000.000 TL’dir [mevzuat-048] Kurum hissesi ödeneği, proje bütçesinin %10’una kadar hesaplanır. | G46: sayfa-akademik__ulusal-destek-programlari__1001-bilimsel-ve-teknolojik-arastirma-projelerini-destekleme-programi mevzuat-048 | H46: 3.000.000, 10 | I46: 1001 | J46: Evet | K46: Doğrulanmadı
A47: q052 | B47: Çok belge | C47: Zor | D47: Patent desteği için bireysel olarak yılda kaç başvuruda destek alabilirim ve ulusal patent başvuruları hâlâ destekleniyor mu? | E47: Gerçek kişiler yılda en fazla 5 patent başvurusu için destek alabilir (Uygulama Esasları). Ancak program sayfasına göre 03.01.2019 tarihli YK kararıyla ulusal patent başvurularına verilen destek ve ödüller başvuruya kapalıdır; PCT kapsamındaki uluslararası başvurular desteklenir. | F47: [mevzuat-068] Gerçek kişiler bir takvim yılı içerisinde en fazla 5 (beş) patent başvurusu için [sayfa-sanayi__ulusal-destek-programlari__1602-tubitak-patent-destek-programi] ulusal patent başvurularına verilen destek ve ödüller başvuruya kapalıdır | G47: mevzuat-068 sayfa-sanayi__ulusal-destek-programlari__1602-tubitak-patent-destek-programi | H47: 5 | I47: 1602 | J47: Evet | K47: Doğrulanmadı
A48: q053 | B48: Çok belge | C48: Orta | D48: 1004 Mükemmeliyet Merkezi programında KOBİ ortağa uygulanacak destek oranı ve araştırma programının azami süresi nedir? | E48: KOBİ'lerin bütçesinin %75'ine kadar destek verilir (büyük ölçekli %60, üniversite/kamu %100); süre en fazla 48 aydır. | F48: [mevzuat-100] KOBİ'lerin bütçesinin %75'ine kadar [sayfa-akademik__ulusal-destek-programlari__1004-mukemmeliyet-merkezi-destek-programi] Süre en fazla 48 ay olabilir. | G48: mevzuat-100 sayfa-akademik__ulusal-destek-programlari__1004-mukemmeliyet-merkezi-destek-programi | H48: 75, 48 | I48: 1004 | J48: Evet | K48: Doğrulanmadı
A49: q054 | B49: Çok belge | C49: Zor | D49: 1501 ve 1507 2026-2 çağrılarına aynı anda başvurmak istiyoruz. Toplam kaç proje önerisi verebiliriz ve 1507'de destek oranı ne olur? | E49: İki çağrı için kuruluş başına toplam en fazla 2 proje önerisi verilebilir (ör. 1+1 ya da 2+0). 1507'de destek oranı her dönem için en fazla %75'tir. | F49: [dosya-3c4c2d391f25] Bu çağrı ile eş zamanlı olarak açılmış olan 1501-Sanayi Ar-Ge Destek Programı 2026 yılı 2. Çağrısına yapılan başvurular da bu limitin uygulanacağı başvuru sayısına dâhildir. [mevzuat-031] Bu programda uygulanacak destek oranı her dönem için en fazla %75 olarak belirlenmiştir. | G49: dosya-3c4c2d391f25 mevzuat-031 | H49: 2, 75 | I49: 1501, 1507 | J49: Evet | K49: Doğrulanmadı
A50: q055 | B50: Çok belge | C50: Zor | D50: ARDEB projesinde süre uzatımı ne kadar yapılabilir, 1501 projesinde durum farklı mı? | E50: ARDEB İdari ve Mali Esaslarına göre proje süresi toplam sürenin en fazla %50'sine kadar uzatılabilir. 1501'de de destek süresi en fazla %50 oranında ve bir defaya mahsus artırılabilir, ancak toplam süre 36 ayı geçemez. | F50: [mevzuat-048] Proje süresi, toplam sürenin en fazla yüzde ellisine kadar uzatılabilir. [mevzuat-030] proje destek süresi otuzaltı ayı geçmemek üzere ve proje destek süresinin en fazla yüzde ellisi (%50) oranında bir defaya mahsus olmak üzere | G50: mevzuat-048 mevzuat-030 | H50: 50, 36 | I50: 1501 | J50: Evet | K50: Doğrulanmadı
A51: q056 | B51: Çok belge | C51: Orta | D51: 1002-A Hızlı Destek ile 1001 arasında proje süresi ve bütçe bakımından fark nedir? | E51: 1002-A'da proje süresi en fazla 12 ay ve destek üst limiti yıllık 150.000 TL'dir; 1001'de süre en fazla 36 ay, üst limit 3.000.000 TL'dir. | F51: [sayfa-akademik__ulusal-destek-programlari__1002-hizli-destek-modulu] Proje süresi en fazla 12 ay olabilir. [sayfa-akademik__ulusal-destek-programlari__1001-bilimsel-ve-teknolojik-arastirma-projelerini-destekleme-programi] Proje süresi en fazla 36 aydır. [sayfa-akademik__ulusal-destek-programlari__1001-bilimsel-ve-teknolojik-arastirma-projelerini-destekleme-programi] yıllık bütçe sınırlaması olmaksızın 3.000.000 TL’dir | G51: sayfa-akademik__ulusal-destek-programlari__1002-hizli-destek-modulu sayfa-akademik__ulusal-destek-programlari__1001-bilimsel-ve-teknolojik-arastirma-projelerini-destekleme-programi | H51: 12, 36, 150.000, 3.000.000 | I51: 1001, 1002 | J51: Evet | K51: Doğrulanmadı
...

Sheet Arama Sonuçları
A1: ID | B1: Tür | C1: Soru | D1: Alıntı sayısı | E1: v0 – sabit pencere (512/64), dense arama | I1: v0r – sabit pencere (512/64), dense arama + reranker | M1: v1 – yapı bazlı parçalama + bağlam başlığı, dense arama | Q1: v2 – yapı bazlı parçalama + bağlam başlığı, hibrit arama (BM25 + dense, RRF) | U1: v3 – yapı bazlı parçalama + bağlam başlığı, hibrit arama (BM25 + dense, RRF) + reranker | Y1: v3b – v3 ile aynı, embedding modeli bge-m3
E2: İlk isabet sırası | F2: R@5 | G2: R@10 | H2: MRR katkısı (1/sıra) | I2: İlk isabet sırası | J2: R@5 | K2: R@10 | L2: MRR katkısı (1/sıra) | M2: İlk isabet sırası | N2: R@5 | O2: R@10 | P2: MRR katkısı (1/sıra) | Q2: İlk isabet sırası | R2: R@5 | S2: R@10 | T2: MRR katkısı (1/sıra) | U2: İlk isabet sırası | V2: R@5 | W2: R@10 | X2: MRR katkısı (1/sıra) | Y2: İlk isabet sırası | Z2: R@5 | AA2: R@10 | AB2: MRR katkısı (1/sıra)
A3: q001 | B3: Tek belge | C3: KOBİ olarak 1507 programından proje desteği alırsam TÜBİTAK harcamalarımın en fazla yüzde kaçını karşılar? | D3: 1 | E3: 28 | F3: 0 | G3: 0 | H3: 0.035714286 | I3: 7 | J3: 0 | K3: 1 | L3: 0.14285714 | M3: 18 | N3: 0 | O3: 0 | P3: 0.055555556 | Q3: — | R3: 0 | S3: 0 | T3: 0 | U3: — | V3: 0 | W3: 0 | X3: 0 | Y3: — | Z3: 0 | AA3: 0 | AB3: 0
A4: q002 | B4: Çok belge | C4: Büyük ölçekli bir firmayız; 1501 programından hangi destek oranıyla yararlanabiliriz? | D4: 2 | E4: — | F4: 0 | G4: 0 | H4: 0 | I4: — | J4: 0 | K4: 0 | L4: 0 | M4: 17 | N4: 0 | O4: 0 | P4: 0.058823529 | Q4: 4 | R4: 0.5 | S4: 0.5 | T4: 0.25 | U4: 3 | V4: 0.5 | W4: 0.5 | X4: 0.33333333 | Y4: 3 | Z4: 0.5 | AA4: 0.5 | AB4: 0.33333333
A5: q003 | B5: Tek belge | C5: 1501 projesinde doktoralı bir personelin aylık maliyeti beyan edilirken brüt asgari ücretin kaç katıyla sınırlandırılır? Lisans mezunu için durum nedir? | D5: 1 | E5: — | F5: 0 | G5: 0 | H5: 0 | I5: — | J5: 0 | K5: 0 | L5: 0 | M5: 1 | N5: 1 | O5: 1 | P5: 1 | Q5: 1 | R5: 1 | S5: 1 | T5: 1 | U5: 1 | V5: 1 | W5: 1 | X5: 1 | Y5: 1 | Z5: 1 | AA5: 1 | AB5: 1
A6: q004 | B6: Tek belge | C6: 1501 projesi için aldığımız kalıp seri üretimde de kullanılacak. Bu kalıbın maliyeti desteğe nasıl dahil edilir? | D6: 1 | E6: — | F6: 0 | G6: 0 | H6: 0 | I6: — | J6: 0 | K6: 0 | L6: 0 | M6: 2 | N6: 1 | O6: 1 | P6: 0.5 | Q6: 1 | R6: 1 | S6: 1 | T6: 1 | U6: 1 | V6: 1 | W6: 1 | X6: 1 | Y6: 1 | Z6: 1 | AA6: 1 | AB6: 1
A7: q005 | B7: Tek belge | C7: 1501'de dönem raporunu (AGY300) son tarihten sonra gönderirsem ne olur, kesinti var mı? | D7: 1 | E7: 8 | F7: 0 | G7: 1 | H7: 0.125 | I7: 2 | J7: 1 | K7: 1 | L7: 0.5 | M7: 3 | N7: 1 | O7: 1 | P7: 0.33333333 | Q7: 2 | R7: 1 | S7: 1 | T7: 0.5 | U7: 3 | V7: 1 | W7: 1 | X7: 0.33333333 | Y7: 3 | Z7: 1 | AA7: 1 | AB7: 0.33333333
A8: q006 | B8: Tek belge | C8: 1507 KOBİ Ar-Ge Başlangıç programında bir firmanın kaç projesi desteklenebiliyor? | D8: 1 | E8: — | F8: 0 | G8: 0 | H8: 0 | I8: — | J8: 0 | K8: 0 | L8: 0 | M8: 21 | N8: 0 | O8: 0 | P8: 0.047619048 | Q8: 17 | R8: 0 | S8: 0 | T8: 0.058823529 | U8: 6 | V8: 0 | W8: 1 | X8: 0.16666667 | Y8: 6 | Z8: 0 | AA8: 1 | AB8: 0.16666667
A9: q007 | B9: Tek belge | C9: 1509 uluslararası projemizde yurt dışından danışmanlık ve hizmet almayı planlıyoruz. Bunun bir sınırı var mı? | D9: 1 | E9: — | F9: 0 | G9: 0 | H9: 0 | I9: — | J9: 0 | K9: 0 | L9: 0 | M9: 1 | N9: 1 | O9: 1 | P9: 1 | Q9: 1 | R9: 1 | S9: 1 | T9: 1 | U9: 1 | V9: 1 | W9: 1 | X9: 1 | Y9: 1 | Z9: 1 | AA9: 1 | AB9: 1
A10: q009 | B10: Tek belge | C10: 1511 projesinde aynı personel için bir ay içinde TÜBİTAK'a kaç günlük maliyet beyan edebilirim? | D10: 1 | E10: 4 | F10: 1 | G10: 1 | H10: 0.25 | I10: 5 | J10: 1 | K10: 1 | L10: 0.2 | M10: 1 | N10: 1 | O10: 1 | P10: 1 | Q10: 1 | R10: 1 | S10: 1 | T10: 1 | U10: 1 | V10: 1 | W10: 1 | X10: 1 | Y10: 1 | Z10: 1 | AA10: 1 | AB10: 1
A11: q010 | B11: Tek belge | C11: 1512 Girişimcilik Destek Programında Aşama 2 iş planı faaliyetleri en fazla ne kadar sürebilir? | D11: 1 | E11: 29 | F11: 0 | G11: 0 | H11: 0.034482759 | I11: 2 | J11: 1 | K11: 1 | L11: 0.5 | M11: 1 | N11: 1 | O11: 1 | P11: 1 | Q11: 3 | R11: 1 | S11: 1 | T11: 0.33333333 | U11: 1 | V11: 1 | W11: 1 | X11: 1 | Y11: 1 | Z11: 1 | AA11: 1 | AB11: 1
A12: q011 | B12: Tek belge | C12: BiGG Yatırım 2026-2 çağrısında TÜBİTAK BİGG Fonu girişim şirketine ne kadar yatırım yapıyor ve karşılığında kaç hisse alıyor? | D12: 1 | E12: 28 | F12: 0 | G12: 0 | H12: 0.035714286 | I12: 10 | J12: 0 | K12: 1 | L12: 0.1 | M12: 1 | N12: 1 | O12: 1 | P12: 1 | Q12: 1 | R12: 1 | S12: 1 | T12: 1 | U12: 3 | V12: 1 | W12: 1 | X12: 0.33333333 | Y12: 3 | Z12: 1 | AA12: 1 | AB12: 0.33333333
A13: q012 | B13: Tek belge | C13: BiGG Yatırım hızlandırma programına kabul edilmek için iş fikrimin değerlendirmede kaç puan alması gerekiyor? | D13: 1 | E13: kapsam reddi | I13: kapsam reddi | M13: kapsam reddi | Q13: kapsam reddi | U13: kapsam reddi | Y13: kapsam reddi
A14: q014 | B14: Tek belge | C14: Sipariş Ar-Ge (1707) 2026-3 çağrısında proje süresi uzatılırsa 24 ayı geçebilir mi? | D14: 1 | E14: — | F14: 0 | G14: 0 | H14: 0 | I14: — | J14: 0 | K14: 0 | L14: 0 | M14: 1 | N14: 1 | O14: 1 | P14: 1 | Q14: 1 | R14: 1 | S14: 1 | T14: 1 | U14: 2 | V14: 1 | W14: 1 | X14: 0.5 | Y14: 2 | Z14: 1 | AA14: 1 | AB14: 0.5
A15: q015 | B15: Tek belge | C15: Eurostars (1709) 2026/2 ulusal çağrısında Türk ortağın proje bütçesi en fazla ne kadar olabilir? | D15: 1 | E15: 2 | F15: 1 | G15: 1 | H15: 0.5 | I15: 2 | J15: 1 | K15: 1 | L15: 0.5 | M15: 1 | N15: 1 | O15: 1 | P15: 1 | Q15: 1 | R15: 1 | S15: 1 | T15: 1 | U15: 1 | V15: 1 | W15: 1 | X15: 1 | Y15: 1 | Z15: 1 | AA15: 1 | AB15: 1
A16: q017 | B16: Tek belge | C16: 1001 projemde aynı anda kaç lisans öğrencisini bursiyer olarak çalıştırabilirim? | D16: 1 | E16: — | F16: 0 | G16: 0 | H16: 0 | I16: — | J16: 0 | K16: 0 | L16: 0 | M16: 1 | N16: 1 | O16: 1 | P16: 1 | Q16: 1 | R16: 1 | S16: 1 | T16: 1 | U16: 1 | V16: 1 | W16: 1 | X16: 1 | Y16: 1 | Z16: 1 | AA16: 1 | AB16: 1
A17: q018 | B17: Tek belge | C17: Özel bir şirkette çalışıyorum; 1001 projesine yürütücü olarak başvurabilmem için şirkette ne kadar süredir çalışıyor olmam gerekir? | D17: 1 | E17: 8 | F17: 0 | G17: 1 | H17: 0.125 | I17: 4 | J17: 1 | K17: 1 | L17: 0.25 | M17: 7 | N17: 0 | O17: 1 | P17: 0.14285714 | Q17: 5 | R17: 1 | S17: 1 | T17: 0.2 | U17: 1 | V17: 1 | W17: 1 | X17: 1 | Y17: 1 | Z17: 1 | AA17: 1 | AB17: 1
A18: q019 | B18: Tek belge | C18: 1002-B Acil Destek Modülünde proje süresi ve bütçe sınırı nedir? | D18: 2 | E18: 1 | F18: 1 | G18: 1 | H18: 1 | I18: 1 | J18: 1 | K18: 1 | L18: 1 | M18: 1 | N18: 0.5 | O18: 0.5 | P18: 1 | Q18: 1 | R18: 0.5 | S18: 1 | T18: 1 | U18: 1 | V18: 1 | W18: 1 | X18: 1 | Y18: 1 | Z18: 1 | AA18: 1 | AB18: 1
A19: q020 | B19: Tek belge | C19: 1003 Öncelikli Alanlar Ar-Ge projeleri en fazla kaç ay sürebilir? | D19: 1 | E19: — | F19: 0 | G19: 0 | H19: 0 | I19: — | J19: 0 | K19: 0 | L19: 0 | M19: 4 | N19: 1 | O19: 1 | P19: 0.25 | Q19: 8 | R19: 0 | S19: 1 | T19: 0.125 | U19: 2 | V19: 1 | W19: 1 | X19: 0.5 | Y19: 2 | Z19: 1 | AA19: 1 | AB19: 0.5
A20: q021 | B20: Tek belge | C20: 1004 Mükemmeliyet Merkezi programında faaliyetlerin hangi Teknoloji Hazırlık Seviyesinde olması bekleniyor? | D20: 1 | E20: — | F20: 0 | G20: 0 | H20: 0 | I20: — | J20: 0 | K20: 0 | L20: 0 | M20: 17 | N20: 0 | O20: 0 | P20: 0.058823529 | Q20: 6 | R20: 0 | S20: 1 | T20: 0.16666667 | U20: 1 | V20: 1 | W20: 1 | X20: 1 | Y20: 1 | Z20: 1 | AA20: 1 | AB20: 1
A21: q022 | B21: Tek belge | C21: 1005 Ulusal Yeni Fikirler ve Ürünler programında bütçe üst limiti ne kadar? | D21: 1 | E21: 1 | F21: 1 | G21: 1 | H21: 1 | I21: 1 | J21: 1 | K21: 1 | L21: 1 | M21: 3 | N21: 1 | O21: 1 | P21: 0.33333333 | Q21: 1 | R21: 1 | S21: 1 | T21: 1 | U21: 1 | V21: 1 | W21: 1 | X21: 1 | Y21: 1 | Z21: 1 | AA21: 1 | AB21: 1
A22: q023 | B22: Tek belge | C22: 1007 programında fizibilite projesi nedir, süresi ne kadar olabilir? | D22: 1 | E22: 18 | F22: 0 | G22: 0 | H22: 0.055555556 | I22: 1 | J22: 1 | K22: 1 | L22: 1 | M22: 8 | N22: 0 | O22: 1 | P22: 0.125 | Q22: 2 | R22: 1 | S22: 1 | T22: 0.5 | U22: 2 | V22: 1 | W22: 1 | X22: 0.5 | Y22: 2 | Z22: 1 | AA22: 1 | AB22: 0.5
A23: q024 | B23: Tek belge | C23: 3001 Başlangıç Ar-Ge projeleri en fazla kaç ay desteklenir? | D23: 1 | E23: — | F23: 0 | G23: 0 | H23: 0 | I23: — | J23: 0 | K23: 0 | L23: 0 | M23: 2 | N23: 1 | O23: 1 | P23: 0.5 | Q23: 3 | R23: 1 | S23: 1 | T23: 0.33333333 | U23: 1 | V23: 1 | W23: 1 | X23: 1 | Y23: 1 | Z23: 1 | AA23: 1 | AB23: 1
A24: q025 | B24: Tek belge | C24: 3501 Kariyer Geliştirme programına doktoramı bitirdikten kaç yıl sonrasına kadar başvurabilirim? | D24: 1 | E24: 3 | F24: 1 | G24: 1 | H24: 0.33333333 | I24: 1 | J24: 1 | K24: 1 | L24: 1 | M24: 6 | N24: 0 | O24: 1 | P24: 0.16666667 | Q24: 10 | R24: 0 | S24: 1 | T24: 0.1 | U24: 1 | V24: 1 | W24: 1 | X24: 1 | Y24: 1 | Z24: 1 | AA24: 1 | AB24: 1
A25: q026 | B25: Tek belge | C25: 2211 Yurt İçi Doktora Burs Programında burs en fazla kaç ay ödenir? | D25: 1 | E25: 4 | F25: 1 | G25: 1 | H25: 0.25 | I25: 1 | J25: 1 | K25: 1 | L25: 1 | M25: 1 | N25: 1 | O25: 1 | P25: 1 | Q25: 1 | R25: 1 | S25: 1 | T25: 1 | U25: 1 | V25: 1 | W25: 1 | X25: 1 | Y25: 1 | Z25: 1 | AA25: 1 | AB25: 1
A26: q027 | B26: Tek belge | C26: 2213 Yurt Dışı Lisansüstü Burs Programında yurt dışında toplam ne kadar süre burs alınabilir? | D26: 1 | E26: 1 | F26: 1 | G26: 1 | H26: 1 | I26: 1 | J26: 1 | K26: 1 | L26: 1 | M26: 1 | N26: 1 | O26: 1 | P26: 1 | Q26: 1 | R26: 1 | S26: 1 | T26: 1 | U26: 1 | V26: 1 | W26: 1 | X26: 1 | Y26: 1 | Z26: 1 | AA26: 1 | AB26: 1
A27: q028 | B27: Tek belge | C27: 2224-A desteğinden aynı yıl içinde ikinci kez yararlanabilir miyim? | D27: 1 | E27: — | F27: 0 | G27: 0 | H27: 0 | I27: — | J27: 0 | K27: 0 | L27: 0 | M27: — | N27: 0 | O27: 0 | P27: 0 | Q27: — | R27: 0 | S27: 0 | T27: 0 | U27: — | V27: 0 | W27: 0 | X27: 0 | Y27: — | Z27: 0 | AA27: 0 | AB27: 0
A28: q029 | B28: Tek belge | C28: 2224-A ile konferansa katıldıktan sonra izleme belgelerini ne kadar süre içinde sisteme yüklemem gerekiyor? | D28: 1 | E28: — | F28: 0 | G28: 0 | H28: 0 | I28: — | J28: 0 | K28: 0 | L28: 0 | M28: — | N28: 0 | O28: 0 | P28: 0 | Q28: — | R28: 0 | S28: 0 | T28: 0 | U28: — | V28: 0 | W28: 0 | X28: 0 | Y28: 3 | Z28: 1 | AA28: 1 | AB28: 0.33333333
A29: q031 | B29: Tek belge | C29: 4007 kapsamında büyük ölçekli bilim festivali düzenlersek ne kadar destek alabiliriz? | D29: 1 | E29: 10 | F29: 0 | G29: 1 | H29: 0.1 | I29: 4 | J29: 1 | K29: 1 | L29: 0.25 | M29: 1 | N29: 1 | O29: 1 | P29: 1 | Q29: 1 | R29: 1 | S29: 1 | T29: 1 | U29: 2 | V29: 1 | W29: 1 | X29: 0.5 | Y29: 2 | Z29: 1 | AA29: 1 | AB29: 0.5
A30: q032 | B30: Tek belge | C30: 4006-A bilim fuarında 20 alt proje sergilenecekse okulumuza toplam ne kadar destek ödenir? | D30: 2 | E30: — | F30: 0 | G30: 0 | H30: 0 | I30: — | J30: 0 | K30: 0 | L30: 0 | M30: 1 | N30: 0.5 | O30: 1 | P30: 1 | Q30: 1 | R30: 1 | S30: 1 | T30: 1 | U30: 1 | V30: 1 | W30: 1 | X30: 1 | Y30: 1 | Z30: 1 | AA30: 1 | AB30: 1
A31: q033 | B31: Tek belge | C31: 4008 projesinde her bir etkinlik dönemi en az kaç gün olmalı? | D31: 1 | E31: 1 | F31: 1 | G31: 1 | H31: 1 | I31: 1 | J31: 1 | K31: 1 | L31: 1 | M31: 16 | N31: 0 | O31: 0 | P31: 0.0625 | Q31: 4 | R31: 1 | S31: 1 | T31: 0.25 | U31: 1 | V31: 1 | W31: 1 | X31: 1 | Y31: 1 | Z31: 1 | AA31: 1 | AB31: 1
A32: q035 | B32: Tek belge | C32: Kurum hissesinden bursiyer ödemesi veya PTİ ödemesi yapabilir miyiz? | D32: 1 | E32: 26 | F32: 0 | G32: 0 | H32: 0.038461538 | I32: 4 | J32: 1 | K32: 1 | L32: 0.25 | M32: 20 | N32: 0 | O32: 0 | P32: 0.05 | Q32: 16 | R32: 0 | S32: 0 | T32: 0.0625 | U32: 5 | V32: 1 | W32: 1 | X32: 0.2 | Y32: 5 | Z32: 1 | AA32: 1 | AB32: 0.2
A33: q036 | B33: Tek belge | C33: TÜBİTAK başvurumun reddine itiraz etmek için kaç günüm var? | D33: 1 | E33: — | F33: 0 | G33: 0 | H33: 0 | I33: — | J33: 0 | K33: 0 | L33: 0 | M33: 3 | N33: 1 | O33: 1 | P33: 0.33333333 | Q33: 3 | R33: 1 | S33: 1 | T33: 0.33333333 | U33: 3 | V33: 1 | W33: 1 | X33: 0.33333333 | Y33: 3 | Z33: 1 | AA33: 1 | AB33: 0.33333333
A34: q037 | B34: Tek belge | C34: ARDEB panel değerlendirmesinde bir panelde kaç panelist bulunur ve en fazla kaç öneri görüşülür? | D34: 1 | E34: 1 | F34: 1 | G34: 1 | H34: 1 | I34: 1 | J34: 1 | K34: 1 | L34: 1 | M34: 21 | N34: 0 | O34: 0 | P34: 0.047619048 | Q34: 14 | R34: 0 | S34: 0 | T34: 0.071428571 | U34: 2 | V34: 1 | W34: 1 | X34: 0.5 | Y34: 2 | Z34: 1 | AA34: 1 | AB34: 0.5
A35: q038 | B35: Tek belge | C35: Teknoparkta yönetici şirketin kurucuları arasında kimlerin bulunması zorunludur? | D35: 1 | E35: 1 | F35: 1 | G35: 1 | H35: 1 | I35: 1 | J35: 1 | K35: 1 | L35: 1 | M35: 1 | N35: 1 | O35: 1 | P35: 1 | Q35: 1 | R35: 1 | S35: 1 | T35: 1 | U35: 1 | V35: 1 | W35: 1 | X35: 1 | Y35: 1 | Z35: 1 | AA35: 1 | AB35: 1
A36: q039 | B36: Tek belge | C36: 5746 sayılı Kanuna göre doktoralı Ar-Ge personelinin gelir vergisi stopajının yüzde kaçı terkin edilir? | D36: 1 | E36: 29 | F36: 0 | G36: 0 | H36: 0.034482759 | I36: 4 | J36: 1 | K36: 1 | L36: 0.25 | M36: 1 | N36: 1 | O36: 1 | P36: 1 | Q36: 1 | R36: 1 | S36: 1 | T36: 1 | U36: 1 | V36: 1 | W36: 1 | X36: 1 | Y36: 1 | Z36: 1 | AA36: 1 | AB36: 1
A37: q040 | B37: Tek belge | C37: Şahıs şirketim var; 1505 projesinde müşteri kuruluş olabilir miyim? | D37: 1 | E37: 3 | F37: 1 | G37: 1 | H37: 0.33333333 | I37: 1 | J37: 1 | K37: 1 | L37: 1 | M37: 10 | N37: 0 | O37: 1 | P37: 0.1 | Q37: 1 | R37: 1 | S37: 1 | T37: 1 | U37: 1 | V37: 1 | W37: 1 | X37: 1 | Y37: 1 | Z37: 1 | AA37: 1 | AB37: 1
A38: q042 | B38: Tek belge | C38: TEYDEB destek limitleri tablosuna göre 1515 Öncül Ar-Ge Laboratuvarları programında proje bütçesi üst limiti nedir? | D38: 1 | E38: — | F38: 0 | G38: 0 | H38: 0 | I38: — | J38: 0 | K38: 0 | L38: 0 | M38: — | N38: 0 | O38: 0 | P38: 0 | Q38: 29 | R38: 0 | S38: 0 | T38: 0.034482759 | U38: 3 | V38: 1 | W38: 1 | X38: 0.33333333 | Y38: 3 | Z38: 1 | AA38: 1 | AB38: 0.33333333
A39: q043 | B39: Tek belge | C39: 1513 Teknoloji Transfer Ofisleri programında Kapasite Geliştirme Aşamasında destek oranı yüzde kaç? | D39: 1 | E39: 2 | F39: 1 | G39: 1 | H39: 0.5 | I39: 1 | J39: 1 | K39: 1 | L39: 1 | M39: 27 | N39: 0 | O39: 0 | P39: 0.037037037 | Q39: — | R39: 0 | S39: 0 | T39: 0 | U39: — | V39: 0 | W39: 0 | X39: 0 | Y39: 4 | Z39: 1 | AA39: 1 | AB39: 0.25
A40: q044 | B40: Çok belge | C40: 1501 Uygulama Esaslarında proje süresi üst sınırı nedir ve 2026 yılı 2. çağrısına kaç aylık proje ile başvurulabilir? | D40: 2 | E40: 29 | F40: 0 | G40: 0 | H40: 0.034482759 | I40: 3 | J40: 0.5 | K40: 0.5 | L40: 0.33333333 | M40: 1 | N40: 0.5 | O40: 0.5 | P40: 1 | Q40: 1 | R40: 0.5 | S40: 0.5 | T40: 1 | U40: 1 | V40: 0.5 | W40: 0.5 | X40: 1 | Y40: 1 | Z40: 0.5 | AA40: 0.5 | AB40: 1
...

Sheet Cevap Sonuçları
A1: ID | B1: Tür | C1: Soru | D1: Beklenen davranış | E1: v0 – sabit pencere (512/64), dense arama | I1: v0r – sabit pencere (512/64), dense arama + reranker | M1: v1 – yapı bazlı parçalama + bağlam başlığı, dense arama | Q1: v2 – yapı bazlı parçalama + bağlam başlığı, hibrit arama (BM25 + dense, RRF) | U1: v3 – yapı bazlı parçalama + bağlam başlığı, hibrit arama (BM25 + dense, RRF) + reranker | Y1: v3b – v3 ile aynı, embedding modeli bge-m3 | AC1: Claude notu – v3 | AD1: Claude notu – v3b
E2: Sistem durumu | F2: Claude kararı | G2: Kaynağa sadık | H2: Beklenen sayılar cevapta | I2: Sistem durumu | J2: Claude kararı | K2: Kaynağa sadık | L2: Beklenen sayılar cevapta | M2: Sistem durumu | N2: Claude kararı | O2: Kaynağa sadık | P2: Beklenen sayılar cevapta | Q2: Sistem durumu | R2: Claude kararı | S2: Kaynağa sadık | T2: Beklenen sayılar cevapta | U2: Sistem durumu | V2: Claude kararı | W2: Kaynağa sadık | X2: Beklenen sayılar cevapta | Y2: Sistem durumu | Z2: Claude kararı | AA2: Kaynağa sadık | AB2: Beklenen sayılar cevapta
A3: q001 | B3: Tek belge | C3: KOBİ olarak 1507 programından proje desteği alırsam TÜBİTAK harcamalarımın en fazla yüzde kaçını karşılar? | D3: Cevap | E3: Cevaplandı | F3: Doğru cevap | G3: Evet | H3: Evet | I3: Cevaplandı | J3: Doğru cevap | K3: Evet | L3: Evet | M3: Cevaplandı | N3: Doğru cevap | O3: Evet | P3: Evet | Q3: Cevaplandı | R3: Doğru cevap | S3: Evet | T3: Evet | U3: Cevaplandı | V3: Doğru cevap | W3: Evet | X3: Evet | Y3: Cevaplandı | Z3: Doğru cevap | AA3: Evet | AB3: Evet
A4: q002 | B4: Çok belge | C4: Büyük ölçekli bir firmayız; 1501 programından hangi destek oranıyla yararlanabiliriz? | D4: Cevap | E4: Cevaplandı | F4: Yanlış cevap | G4: Kararsız | H4: Hayır | I4: Cevaplandı | J4: Yanlış cevap | K4: Evet | L4: Hayır | M4: Cevaplandı | N4: Yanlış cevap | O4: Hayır | P4: Hayır | Q4: Cevaplandı | R4: Yanlış cevap | S4: Evet | T4: Hayır | U4: Cevaplandı | V4: Yanlış cevap | W4: Evet | X4: Hayır | Y4: Cevaplandı | Z4: Yanlış cevap | AA4: Evet | AB4: Hayır | AC4: 2026-2 çağrısına büyük firmanın başvuramayacağı bilgisi eksik | AD4: 2026-2 çağrısına büyük firmanın başvuramayacağı bilgisi eksik
A5: q003 | B5: Tek belge | C5: 1501 projesinde doktoralı bir personelin aylık maliyeti beyan edilirken brüt asgari ücretin kaç katıyla sınırlandırılır? Lisans mezunu için durum nedir? | D5: Cevap | E5: Cevaplandı | F5: Yanlış cevap | G5: Hayır | H5: Hayır | I5: Cevaplandı | J5: Yanlış cevap | K5: Hayır | L5: Hayır | M5: Cevaplandı | N5: Doğru cevap | O5: Evet | P5: Evet | Q5: Cevaplandı | R5: Doğru cevap | S5: Evet | T5: Evet | U5: Cevaplandı | V5: Yanlış cevap | W5: Hayır | X5: Hayır | Y5: Cevaplandı | Z5: Yanlış cevap | AA5: Hayır | AB5: Hayır | AC5: 1501'de lisans için 8 kat; 10/6 kat başka programdan aktarılmış | AD5: 1501'de lisans için 8 kat; 10/6 kat başka programdan aktarılmış
A6: q004 | B6: Tek belge | C6: 1501 projesi için aldığımız kalıp seri üretimde de kullanılacak. Bu kalıbın maliyeti desteğe nasıl dahil edilir? | D6: Cevap | E6: Cevaplandı | F6: Yanlış cevap | G6: Hayır | H6: Hayır | I6: Cevaplandı | J6: Yanlış cevap | K6: Kararsız | L6: Evet | M6: Cevaplandı | N6: Doğru cevap | O6: Kararsız | P6: Evet | Q6: Cevaplandı | R6: Doğru cevap | S6: Evet | T6: Evet | U6: Cevaplandı | V6: Doğru cevap | W6: Evet | X6: Evet | Y6: Cevaplandı | Z6: Doğru cevap | AA6: Evet | AB6: Evet
A7: q005 | B7: Tek belge | C7: 1501'de dönem raporunu (AGY300) son tarihten sonra gönderirsem ne olur, kesinti var mı? | D7: Cevap | E7: Cevaplandı | F7: Yanlış cevap | G7: Kararsız | H7: Evet | I7: Cevaplandı | J7: Yanlış cevap | K7: Evet | L7: Hayır | M7: Cevaplandı | N7: Yanlış cevap | O7: Hayır | P7: Evet | Q7: Cevaplandı | R7: Yanlış cevap | S7: Hayır | T7: Evet | U7: Cevaplandı | V7: Yanlış cevap | W7: Hayır | X7: Evet | Y7: Cevaplandı | Z7: Yanlış cevap | AA7: Hayır | AB7: Evet | AC7: Günlük %1 kesinti eksik; kaynak %30 kesintiyi desteklemiyor | AD7: Günlük %1 kesinti eksik; kaynak %30 kesintiyi desteklemiyor
A8: q006 | B8: Tek belge | C8: 1507 KOBİ Ar-Ge Başlangıç programında bir firmanın kaç projesi desteklenebiliyor? | D8: Cevap | E8: Cevaplandı | F8: Doğru cevap | G8: Evet | H8: Evet | I8: Cevaplandı | J8: Doğru cevap | K8: Evet | L8: Evet | M8: Cevaplandı | N8: Doğru cevap | O8: Evet | P8: Evet | Q8: Cevaplandı | R8: Doğru cevap | S8: Evet | T8: Evet | U8: Cevaplandı | V8: Doğru cevap | W8: Evet | X8: Evet | Y8: Cevaplandı | Z8: Doğru cevap | AA8: Evet | AB8: Evet
A9: q007 | B9: Tek belge | C9: 1509 uluslararası projemizde yurt dışından danışmanlık ve hizmet almayı planlıyoruz. Bunun bir sınırı var mı? | D9: Cevap | E9: Cevaplandı | F9: Yanlış cevap | G9: Hayır | H9: Hayır | I9: Cevaplandı | J9: Doğru cevap | K9: Hayır | L9: Evet | M9: Cevaplandı | N9: Doğru cevap | O9: Evet | P9: Evet | Q9: Cevaplandı | R9: Doğru cevap | S9: Evet | T9: Evet | U9: Cevaplandı | V9: Doğru cevap | W9: Hayır | X9: Evet | Y9: Cevaplandı | Z9: Doğru cevap | AA9: Hayır | AB9: Evet | AC9: %50'ye artırma Yenilik Destek Yönergesinden, 1509 için değil | AD9: %50'ye artırma Yenilik Destek Yönergesinden, 1509 için değil
A10: q009 | B10: Tek belge | C10: 1511 projesinde aynı personel için bir ay içinde TÜBİTAK'a kaç günlük maliyet beyan edebilirim? | D10: Cevap | E10: Cevaplandı | F10: Doğru cevap | G10: Evet | H10: Evet | I10: Cevaplandı | J10: Doğru cevap | K10: Evet | L10: Evet | M10: Cevaplandı | N10: Doğru cevap | O10: Evet | P10: Evet | Q10: Cevaplandı | R10: Doğru cevap | S10: Evet | T10: Evet | U10: Cevaplandı | V10: Doğru cevap | W10: Evet | X10: Evet | Y10: Cevaplandı | Z10: Doğru cevap | AA10: Evet | AB10: Evet
A11: q010 | B11: Tek belge | C11: 1512 Girişimcilik Destek Programında Aşama 2 iş planı faaliyetleri en fazla ne kadar sürebilir? | D11: Cevap | E11: Cevaplandı | F11: Yanlış cevap | G11: Hayır | H11: Hayır | I11: Cevaplandı | J11: Doğru cevap | K11: Kararsız | L11: Evet | M11: Cevaplandı | N11: Doğru cevap | O11: Evet | P11: Evet | Q11: Cevaplandı | R11: Doğru cevap | S11: Evet | T11: Evet | U11: Cevaplandı | V11: Doğru cevap | W11: Evet | X11: Evet | Y11: Cevaplandı | Z11: Doğru cevap | AA11: Evet | AB11: Evet
A12: q011 | B12: Tek belge | C12: BiGG Yatırım 2026-2 çağrısında TÜBİTAK BİGG Fonu girişim şirketine ne kadar yatırım yapıyor ve karşılığında kaç hisse alıyor? | D12: Cevap | E12: Cevaplandı | F12: Yanlış cevap | G12: Evet | H12: Hayır | I12: Cevaplandı | J12: Yanlış cevap | K12: Hayır | L12: Hayır | M12: Cevaplandı | N12: Doğru cevap | O12: Evet | P12: Evet | Q12: Cevaplandı | R12: Doğru cevap | S12: Evet | T12: Evet | U12: Cevaplandı | V12: Yanlış cevap | W12: Evet | X12: Hayır | Y12: Cevaplandı | Z12: Yanlış cevap | AA12: Evet | AB12: Hayır | AC12: Güncel tutar 1.350.000 TL; eski SSS değeri 900.000 verilmiş | AD12: Güncel tutar 1.350.000 TL; eski SSS değeri 900.000 verilmiş
A13: q012 | B13: Tek belge | C13: BiGG Yatırım hızlandırma programına kabul edilmek için iş fikrimin değerlendirmede kaç puan alması gerekiyor? | D13: Cevap | E13: Ret: kapsam dışı | F13: Gereksiz ret (üretim) | H13: Hayır | I13: Ret: kapsam dışı | J13: Gereksiz ret (üretim) | L13: Hayır | M13: Ret: kapsam dışı | N13: Gereksiz ret (üretim) | P13: Hayır | Q13: Ret: kapsam dışı | R13: Gereksiz ret (üretim) | T13: Hayır | U13: Ret: kapsam dışı | V13: Gereksiz ret (üretim) | X13: Hayır | Y13: Ret: kapsam dışı | Z13: Gereksiz ret (üretim) | AB13: Hayır | AC13: Kapsam filtresi alan içi soruyu reddetti; kaynak getirilmedi | AD13: Kapsam filtresi alan içi soruyu reddetti; kaynak getirilmedi
A14: q014 | B14: Tek belge | C14: Sipariş Ar-Ge (1707) 2026-3 çağrısında proje süresi uzatılırsa 24 ayı geçebilir mi? | D14: Cevap | E14: Cevaplandı | F14: Yanlış cevap | G14: Hayır | H14: Evet | I14: Cevaplandı | J14: Doğru cevap | K14: Kararsız | L14: Evet | M14: Cevaplandı | N14: Doğru cevap | O14: Evet | P14: Evet | Q14: Cevaplandı | R14: Doğru cevap | S14: Evet | T14: Evet | U14: Cevaplandı | V14: Doğru cevap | W14: Evet | X14: Evet | Y14: Cevaplandı | Z14: Doğru cevap | AA14: Evet | AB14: Evet
A15: q015 | B15: Tek belge | C15: Eurostars (1709) 2026/2 ulusal çağrısında Türk ortağın proje bütçesi en fazla ne kadar olabilir? | D15: Cevap | E15: Cevaplandı | F15: Doğru cevap | G15: Kararsız | H15: Evet | I15: Cevaplandı | J15: Doğru cevap | K15: Kararsız | L15: Evet | M15: Cevaplandı | N15: Doğru cevap | O15: Evet | P15: Evet | Q15: Cevaplandı | R15: Doğru cevap | S15: Evet | T15: Evet | U15: Cevaplandı | V15: Doğru cevap | W15: Evet | X15: Evet | Y15: Cevaplandı | Z15: Doğru cevap | AA15: Evet | AB15: Evet
A16: q017 | B16: Tek belge | C16: 1001 projemde aynı anda kaç lisans öğrencisini bursiyer olarak çalıştırabilirim? | D16: Cevap | E16: Cevaplandı | F16: Doğru cevap | G16: Evet | H16: Evet | I16: Cevaplandı | J16: Yanlış cevap | K16: Hayır | L16: Hayır | M16: Cevaplandı | N16: Doğru cevap | O16: Evet | P16: Evet | Q16: Cevaplandı | R16: Doğru cevap | S16: Evet | T16: Evet | U16: Cevaplandı | V16: Doğru cevap | W16: Evet | X16: Evet | Y16: Cevaplandı | Z16: Doğru cevap | AA16: Evet | AB16: Evet
